Workbook

Sheet 令和8年7月
A1: 天理 | F1: 店 | G1: 売上表 | H1: 令和8年 | M1: 7月 | AX1: 部門別売上＆構成比
AV3: 95 | AW3: 1 | AY3: 2 | BA3: 3 | BC3: 4 | BE3: 6 | BG3: 7 | BI3: 8 | BK3: 9 | BM3: 10 | BO3: 11 | BQ3: 12 | BS3: 15 | BU3: 28 | BW3: 33 | BY3: 40 | CA3: 41 | CC3: 45 | CE3: 46 | CG3: 36 | CI3: 47 | CK3: 31 | CM3: 48
A4: 日付 | B4: 曜日 | C4: 最高 気温 | D4: 最低 気温 | E4: 天気 | F4: 売上 | G4: 累計売上 | H4: 前年対比 | I4: 前年対比 (曜日合わせ) | J4: 目標売上対比 | K4: 客数 | L4: 前年比 | M4: 客単価 | N4: 前年比 | O4: 1品当の 平均価格 | P4: 点数 | Q4: 1人当の 買上点数 | R4: 前年 最高気温 | S4: 前年 最低気温 | T4: 前年天気 | U4: 前年売上 | V4: 前年累計売上 | W4: 前年客数 | X4: 前年客単 | Y4: 前々年売上 | Z4: 前々年売上累計 | AA4: 前々年売上対比 | AB4: 目標売上 | AC4: 目標売上累計 | AD4: PayPay | AE4: クレジット | AF4: ID | AG4: 交通IC | AH4: 楽天edy | AI4: WAON | AJ4: nanaco | AK4: 銀聯 | AL4: Quickpay | AM4: フリー① | AN4: フリー② | AO4: フリー③ | AP4: フリー④ | AQ4: フリー⑤ | AR4: キャッシュレス合計 | AS4: 構成比 | AT4: 入金額 | AV4: カテゴリー | AW4: お菓子 | AX4: 構成比 | AY4: 珍味 | AZ4: 構成比 | BA4: チビッコ | BB4: 構成比 | BC4: ドリンク | BD4: 構成比 | BE4: 米 | BF4: 構成比 | BG4: 半生 | BH4: 構成比 | BI4: 飴 | BJ4: 構成比 | BK4: おもちゃ | BL4: 構成比 | BM4: ポケット | BN4: 構成比 | BO4: 米菓 | BP4: 構成比 | BQ4: ゼリー | BR4: 構成比 | BS4: 袋 | BT4: 構成比 | BU4: 8円 | BV4: 構成比 | BW4: 88円均一 | BX4: 構成比 | BY4: 季節① | BZ4: 構成比 | CA4: 季節② | CB4: 構成比 | CC4: 龍屋 | CD4: 構成比 | CE4: リンクス | CF4: 構成比 | CG4: ヤマト | CH4: 構成比 | CI4: 瓶ラムネ | CJ4: 構成比 | CK4: ハロウィン | CL4: 構成比 | CM4: 昔なつ菓子 | CN4: 構成比 | CO4: フリー⑥ | CP4: 構成比 | CQ4: フリー⑦ | CR4: 構成比 | CS4: フリー⑧ | CT4: 構成比 | CU4: うち相違 | CV4: レジマイナス | CX4: 開店後１時間 | CY4: 客数 | CZ4: 閉店前１時間売上 | DA4: 客数 | DB4: 日付 | DC4: 曜日 | DD4: 終了 | DF4: 50枚白 | DG4: 50枚アプ | DH4: KF94白 | DI4: KF94ベージュ | DJ4: 小顔マスク | DK4: フリー① | DL4: フリー② | DM4: フリー③ | DN4: フリー④ | DO4: フリー⑤ | DP4: マスク合計 | DQ4: 構成比 | DS4: 理由 | DW4: 金額 | DX4: 引くor足す
A5: 1 | B5: 水 | C5: 24 | D5: 20 | E5: 曇 | F5: 131517 | G5: =IF(SUM($F$5:F5)=0,"",SUM($F$5:F5)) -> 131517 | H5: =IF(ISERROR(G5/V5),"",(G5/V5)) -> 1.1980378 | I5: =IF($A6="",$G5/($V5-$U$5+INDIRECT(IF(_xlfn.SHEET()<6,"令和8年"&_xlfn.SHEET()+7&"月","令和9年"&_xlfn.SHEET()-5&"月")&"!$U$5")),$G5/($V6-$U$5)) -> 1.7692949 | J5: =IFERROR(G5/AC5,"") -> 0.657585 | K5: 83 | L5: =IF(ISERROR(K5/W5),"",(K5/W5)) -> 1.3833333 | M5: =IF(ISERROR(F5/K5),"",(F5/K5)) -> 1584.5422 | N5: =IF(ISERROR(M5/X5),"",(M5/X5)) -> 0.86605145 | O5: =IF(ISERROR(F5/P5),"",(F5/P5)) -> 56.036216 | P5: 2347 | Q5: =IF(ISERROR(P5/K5),"",(P5/K5)) -> 28.277108 | R5: 35 | S5: 25 | T5: 晴 | U5: 109777 | V5: =SUM(U5) -> 109777 | W5: 60 | X5: =IF(ISERROR(U5/W5),"",(U5/W5)) -> 1829.6167 | Y5: 250044 | Z5: =SUM(Y5) -> 250044 | AA5: =IF(ISERROR(V5/Z5),"",(V5/Z5)) -> 0.43903073 | AB5: 200000 | AC5: =AB5 -> 200000 | AD5: 20333 | AE5: 3922 | AF5: 5922 | AG5: 0 | AH5: 0 | AI5: 1011 | AJ5: 0 | AK5: 0 | AL5: 0 | AM5: 0 | AN5: 0 | AR5: =SUM(AD5:AQ5) -> 31188 | AS5: =IF(ISERROR((AR5/F5)),"",AR5/F5) -> 0.23714045 | AT5: =F5-AR5+DW5 -> 100329 | AV5: =A5 -> 1 | AW5: 31070 | AX5: =IF(ISERROR((AW5/$F5)),"",AW5/$F5) -> 0.23624322 | AY5: 1996 | AZ5: =IF(ISERROR((AY5/$F5)),"",AY5/$F5) -> 0.015176745 | BA5: 48495 | BB5: =IF(ISERROR((BA5/$F5)),"",BA5/$F5) -> 0.3687356 | BC5: 2628 | BD5: =IF(ISERROR((BC5/$F5)),"",BC5/$F5) -> 0.019982208 | BE5: 0 | BF5: =IF(ISERROR((BE5/$F5)),"",BE5/$F5) -> 0 | BG5: 2455 | BH5: =IF(ISERROR((BG5/$F5)),"",BG5/$F5) -> 0.018666788 | BI5: 794 | BJ5: =IF(ISERROR((BI5/$F5)),"",BI5/$F5) -> 0.0060372423 | BK5: 2308 | BL5: =IF(ISERROR((BK5/$F5)),"",BK5/$F5) -> 0.017549062 | BM5: 19895 | BN5: =IF(ISERROR((BM5/$F5)),"",BM5/$F5) -> 0.15127322 | BO5: 1022 | BP5: =IF(ISERROR((BO5/$F5)),"",BO5/$F5) -> 0.0077708585 | BQ5: 1208 | BR5: =IF(ISERROR((BQ5/$F5)),"",BQ5/$F5) -> 0.0091851244 | BS5: 125 | BT5: =IF(ISERROR((BS5/$F5)),"",BS5/$F5) -> 0.00095044747 | BU5: 0 | BV5: =IF(ISERROR((BU5/$F5)),"",BU5/$F5) -> 0 | BW5: 295 | BX5: =IF(ISERROR((BW5/$F5)),"",BW5/$F5) -> 0.002243056 | BY5: 0 | BZ5: =IF(ISERROR((BY5/$F5)),"",BY5/$F5) -> 0 | CA5: 0 | CB5: =IF(ISERROR((CA5/$F5)),"",CA5/$F5) -> 0 | CC5: 625 | CD5: =IF(ISERROR((CC5/$F5)),"",CC5/$F5) -> 0.0047522374 | CE5: 700 | CF5: =IF(ISERROR((CE5/$F5)),"",CE5/$F5) -> 0.0053225058 | CG5: 0 | CH5: =IF(ISERROR((CG5/$F5)),"",CG5/$F5) -> 0 | CI5: 590 | CJ5: =IF(ISERROR((CI5/$F5)),"",CI5/$F5) -> 0.0044861121 | CK5: 0 | CL5: =IF(ISERROR((CK5/$F5)),"",CK5/$F5) -> 0 | CM5: 0 | CN5: =IF(ISERROR((CM5/$F5)),"",CM5/$F5) -> 0 | CP5: =IF(ISERROR((CO5/$F5)),"",CO5/$F5) -> 0 | CR5: =IF(ISERROR((CQ5/$F5)),"",CQ5/$F5) -> 0 | CT5: =IF(ISERROR((CS5/$F5)),"",CS5/$F5) -> 0 | CX5: 25550 | CY5: 11 | CZ5: 5386 | DA5: 18 | DB5: 1 | DC5: =B5 -> 水 | DP5: =SUM(DF5:DO5) -> 0 | DQ5: =IF(ISERROR((DP5/F5)),"",DP5/F5) -> 0
A6: 2 | B6: 木 | C6: 25 | D6: 21 | E6: 雨 | F6: 89893 | G6: =IF(SUM($F$5:F6)=0,"",SUM($F$5:F6)) -> 221410 | H6: =IF(ISERROR(G6/V6),"",(G6/V6)) -> 1.2025963 | I6: =IF($A7="",$G6/($V6-$U$5+INDIRECT(IF(_xlfn.SHEET()<6,"令和8年"&_xlfn.SHEET()+7&"月","令和9年"&_xlfn.SHEET()-5&"月")&"!$U$5")),$G6/($V7-$U$5)) -> 1.3174697 | J6: =IFERROR(G6/AC6,"") -> 0.553525 | K6: 82 | L6: =IF(ISERROR(K6/W6),"",(K6/W6)) -> 1.64 | M6: =IF(ISERROR(F6/K6),"",(F6/K6)) -> 1096.2561 | N6: =IF(ISERROR(M6/X6),"",(M6/X6)) -> 0.7373953 | O6: =IF(ISERROR(F6/P6),"",(F6/P6)) -> 48.071123 | P6: 1870 | Q6: =IF(ISERROR(P6/K6),"",(P6/K6)) -> 22.804878 | R6: 35 | S6: 26 | T6: 晴 | U6: 74333 | V6: =SUM(V5+U6) -> 184110 | W6: 50 | X6: =IF(ISERROR(U6/W6),"",(U6/W6)) -> 1486.66 | Y6: 165632 | Z6: =SUM(Z5+Y6) -> 415676 | AA6: =IF(ISERROR(V6/Z6),"",(V6/Z6)) -> 0.44291708 | AB6: 200000 | AC6: =AB6+AC5 -> 400000 | AD6: 10552 | AE6: 7684 | AF6: 2311 | AG6: 0 | AH6: 0 | AI6: 2047 | AJ6: 0 | AK6: 0 | AL6: 0 | AM6: 0 | AN6: 0 | AR6: =SUM(AD6:AQ6) -> 22594 | AS6: =IF(ISERROR((AR6/F6)),"",AR6/F6) -> 0.25134326 | AT6: =F6-AR6+DW6 -> 67299 | AV6: =A6 -> 2 | AW6: 16559 | AX6: =IF(ISERROR((AW6/$F6)),"",AW6/$F6) -> 0.18420789 | AY6: 0 | AZ6: =IF(ISERROR((AY6/$F6)),"",AY6/$F6) -> 0 | BA6: 38140 | BB6: =IF(ISERROR((BA6/$F6)),"",BA6/$F6) -> 0.4242822 | BC6: 386 | BD6: =IF(ISERROR((BC6/$F6)),"",BC6/$F6) -> 0.004293994 | BE6: 0 | BF6: =IF(ISERROR((BE6/$F6)),"",BE6/$F6) -> 0 | BG6: 960 | BH6: =IF(ISERROR((BG6/$F6)),"",BG6/$F6) -> 0.010679363 | BI6: 856 | BJ6: =IF(ISERROR((BI6/$F6)),"",BI6/$F6) -> 0.0095224322 | BK6: 1455 | BL6: =IF(ISERROR((BK6/$F6)),"",BK6/$F6) -> 0.01618591 | BM6: 17365 | BN6: =IF(ISERROR((BM6/$F6)),"",BM6/$F6) -> 0.19317411 | BO6: 1073 | BP6: =IF(ISERROR((BO6/$F6)),"",BO6/$F6) -> 0.011936413 | BQ6: 138 | BR6: =IF(ISERROR((BQ6/$F6)),"",BQ6/$F6) -> 0.0015351585 | BS6: 145 | BT6: =IF(ISERROR((BS6/$F6)),"",BS6/$F6) -> 0.0016130288 | BU6: 0 | BV6: =IF(ISERROR((BU6/$F6)),"",BU6/$F6) -> 0 | BW6: 0 | BX6: =IF(ISERROR((BW6/$F6)),"",BW6/$F6) -> 0 | BY6: 0 | BZ6: =IF(ISERROR((BY6/$F6)),"",BY6/$F6) -> 0 | CA6: 0 | CB6: =IF(ISERROR((CA6/$F6)),"",CA6/$F6) -> 0 | CC6: 730 | CD6: =IF(ISERROR((CC6/$F6)),"",CC6/$F6) -> 0.0081207658 | CE6: 320 | CF6: =IF(ISERROR((CE6/$F6)),"",CE6/$F6) -> 0.0035597877 | CG6: 0 | CH6: =IF(ISERROR((CG6/$F6)),"",CG6/$F6) -> 0 | CI6: 354 | CJ6: =IF(ISERROR((CI6/$F6)),"",CI6/$F6) -> 0.0039380152 | CK6: 0 | CL6: =IF(ISERROR((CK6/$F6)),"",CK6/$F6) -> 0 | CM6: 0 | CN6: =IF(ISERROR((CM6/$F6)),"",CM6/$F6) -> 0 | CP6: =IF(ISERROR((CO6/$F6)),"",CO6/$F6) -> 0 | CR6: =IF(ISERROR((CQ6/$F6)),"",CQ6/$F6) -> 0 | CT6: =IF(ISERROR((CS6/$F6)),"",CS6/$F6) -> 0 | CX6: 7305 | CY6: 2 | CZ6: 6562 | DA6: 14 | DB6: 2 | DC6: =B6 -> 木 | DP6: =SUM(DF6:DO6) -> 0 | DQ6: =IF(ISERROR((DP6/F6)),"",DP6/F6) -> 0
A7: 3 | B7: 金 | C7: 31 | D7: 20 | E7: 晴 | F7: 127666 | G7: =IF(SUM($F$5:F7)=0,"",SUM($F$5:F7)) -> 349076 | H7: =IF(ISERROR(G7/V7),"",(G7/V7)) -> 1.2564193 | I7: {=IF($A8="",$G7/($V7-$U$5+INDIRECT(IF(_xlfn.SHEET()<6,"令和8年"&_xlfn.SHEET()+7&"月","令和9年"&_xlfn.SHEET()-5&"月")&"!$U$5")),$G7/($V8-$U$5))} -> 1.2823305 | J7: =IFERROR(G7/AC7,"") -> 0.58179333 | K7: 91 | L7: =IF(ISERROR(K7/W7),"",(K7/W7)) -> 1.4918033 | M7: =IF(ISERROR(F7/K7),"",(F7/K7)) -> 1402.9231 | N7: =IF(ISERROR(M7/X7),"",(M7/X7)) -> 0.91308851 | O7: =IF(ISERROR(F7/P7),"",(F7/P7)) -> 55.314558 | P7: 2308 | Q7: =IF(ISERROR(P7/K7),"",(P7/K7)) -> 25.362637 | R7: 35 | S7: 26 | T7: 晴/雨 | U7: 93724 | V7: =SUM(V6+U7) -> 277834 | W7: 61 | X7: =IF(ISERROR(U7/W7),"",(U7/W7)) -> 1536.459 | Y7: 180988 | Z7: =SUM(Z6+Y7) -> 596664 | AA7: =IF(ISERROR(V7/Z7),"",(V7/Z7)) -> 0.46564566 | AB7: 200000 | AC7: =AB7+AC6 -> 600000 | AD7: 20565 | AE7: 2778 | AF7: 0 | AG7: 0 | AH7: 0 | AI7: 208 | AJ7: 0 | AK7: 0 | AL7: 2586 | AM7: 0 | AN7: 0 | AR7: =SUM(AD7:AQ7) -> 26137 | AS7: =IF(ISERROR((AR7/F7)),"",AR7/F7) -> 0.20472953 | AT7: =F7-AR7+DW7 -> 101529 | AV7: =A7 -> 3 | AW7: 30940 | AX7: =IF(ISERROR((AW7/$F7)),"",AW7/$F7) -> 0.24235113 | AY7: 1836 | AZ7: =IF(ISERROR((AY7/$F7)),"",AY7/$F7) -> 0.014381276 | BA7: 43491 | BB7: =IF(ISERROR((BA7/$F7)),"",BA7/$F7) -> 0.34066235 | BC7: 1274 | BD7: =IF(ISERROR((BC7/$F7)),"",BC7/$F7) -> 0.0099791644 | BE7: 0 | BF7: =IF(ISERROR((BE7/$F7)),"",BE7/$F7) -> 0 | BG7: 3782 | BH7: =IF(ISERROR((BG7/$F7)),"",BG7/$F7) -> 0.029624176 | BI7: 1006 | BJ7: =IF(ISERROR((BI7/$F7)),"",BI7/$F7) -> 0.0078799367 | BK7: 1658 | BL7: =IF(ISERROR((BK7/$F7)),"",BK7/$F7) -> 0.012987013 | BM7: 23938 | BN7: =IF(ISERROR((BM7/$F7)),"",BM7/$F7) -> 0.1875049 | BO7: 796 | BP7: =IF(ISERROR((BO7/$F7)),"",BO7/$F7) -> 0.0062350195 | BQ7: 892 | BR7: =IF(ISERROR((BQ7/$F7)),"",BQ7/$F7) -> 0.0069869817 | BS7: 260 | BT7: =IF(ISERROR((BS7/$F7)),"",BS7/$F7) -> 0.0020365642 | BU7: 0 | BV7: =IF(ISERROR((BU7/$F7)),"",BU7/$F7) -> 0 | BW7: 390 | BX7: =IF(ISERROR((BW7/$F7)),"",BW7/$F7) -> 0.0030548462 | BY7: 0 | BZ7: =IF(ISERROR((BY7/$F7)),"",BY7/$F7) -> 0 | CA7: 0 | CB7: =IF(ISERROR((CA7/$F7)),"",CA7/$F7) -> 0 | CC7: 100 | CD7: =IF(ISERROR((CC7/$F7)),"",CC7/$F7) -> 0.00078329391 | CE7: 0 | CF7: =IF(ISERROR((CE7/$F7)),"",CE7/$F7) -> 0 | CG7: 0 | CH7: =IF(ISERROR((CG7/$F7)),"",CG7/$F7) -> 0 | CI7: 472 | CJ7: =IF(ISERROR((CI7/$F7)),"",CI7/$F7) -> 0.0036971472 | CK7: 0 | CL7: =IF(ISERROR((CK7/$F7)),"",CK7/$F7) -> 0 | CM7: 0 | CN7: =IF(ISERROR((CM7/$F7)),"",CM7/$F7) -> 0 | CP7: =IF(ISERROR((CO7/$F7)),"",CO7/$F7) -> 0 | CR7: =IF(ISERROR((CQ7/$F7)),"",CQ7/$F7) -> 0 | CT7: =IF(ISERROR((CS7/$F7)),"",CS7/$F7) -> 0 | CX7: 5692 | CY7: 21 | CZ7: 1703 | DA7: 12 | DB7: 3 | DC7: =B7 -> 金 | DP7: =SUM(DF7:DO7) -> 0 | DQ7: =IF(ISERROR((DP7/F7)),"",DP7/F7) -> 0
A8: 4 | B8: 土 | C8: 28 | D8: 22 | E8: 曇/雨 | F8: 390664 | G8: =IF(SUM($F$5:F8)=0,"",SUM($F$5:F8)) -> 739740 | H8: =IF(ISERROR(G8/V8),"",(G8/V8)) -> 1.9365074 | I8: {=IF($A9="",$G8/($V8-$U$5+INDIRECT(IF(_xlfn.SHEET()<6,"令和8年"&_xlfn.SHEET()+7&"月","令和9年"&_xlfn.SHEET()-5&"月")&"!$U$5")),$G8/($V9-$U$5))} -> 0.97011647 | J8: =IFERROR(G8/AC8,"") -> 0.64325217 | K8: 255 | L8: =IF(ISERROR(K8/W8),"",(K8/W8)) -> 3.4459459 | M8: =IF(ISERROR(F8/K8),"",(F8/K8)) -> 1532.0157 | N8: =IF(ISERROR(M8/X8),"",(M8/X8)) -> 1.0883823 | O8: =IF(ISERROR(F8/P8),"",(F8/P8)) -> 57.248535 | P8: 6824 | Q8: =IF(ISERROR(P8/K8),"",(P8/K8)) -> 26.760784 | R8: 35 | S8: 25 | T8: 晴 | U8: 104163 | V8: =SUM(V7+U8) -> 381997 | W8: 74 | X8: =IF(ISERROR(U8/W8),"",(U8/W8)) -> 1407.6081 | Y8: 149991 | Z8: =SUM(Z7+Y8) -> 746655 | AA8: =IF(ISERROR(V8/Z8),"",(V8/Z8)) -> 0.51161112 | AB8: 550000 | AC8: =AB8+AC7 -> 1150000 | AD8: 52789 | AE8: 59063 | AF8: 8402 | AG8: 2218 | AH8: 1331 | AI8: 6814 | AJ8: 0 | AK8: 0 | AL8: 14489 | AM8: 0 | AN8: 0 | AR8: =SUM(AD8:AQ8) -> 145106 | AS8: =IF(ISERROR((AR8/F8)),"",AR8/F8) -> 0.37143428 | AT8: =F8-AR8+DW8 -> 245558 | AV8: =A8 -> 4 | AW8: 69870 | AX8: =IF(ISERROR((AW8/$F8)),"",AW8/$F8) -> 0.17884934 | AY8: 3270 | AZ8: =IF(ISERROR((AY8/$F8)),"",AY8/$F8) -> 0.0083703643 | BA8: 133875 | BB8: =IF(ISERROR((BA8/$F8)),"",BA8/$F8) -> 0.34268579 | BC8: 7366 | BD8: =IF(ISERROR((BC8/$F8)),"",BC8/$F8) -> 0.018855078 | BE8: 0 | BF8: =IF(ISERROR((BE8/$F8)),"",BE8/$F8) -> 0 | BG8: 6095 | BH8: =IF(ISERROR((BG8/$F8)),"",BG8/$F8) -> 0.015601642 | BI8: 3398 | BJ8: =IF(ISERROR((BI8/$F8)),"",BI8/$F8) -> 0.0086980116 | BK8: 16497 | BL8: =IF(ISERROR((BK8/$F8)),"",BK8/$F8) -> 0.042228104 | BM8: 81018 | BN8: =IF(ISERROR((BM8/$F8)),"",BM8/$F8) -> 0.20738537 | BO8: 2275 | BP8: =IF(ISERROR((BO8/$F8)),"",BO8/$F8) -> 0.0058234186 | BQ8: 1246 | BR8: =IF(ISERROR((BQ8/$F8)),"",BQ8/$F8) -> 0.0031894416 | BS8: 540 | BT8: =IF(ISERROR((BS8/$F8)),"",BS8/$F8) -> 0.001382262 | BU8: 0 | BV8: =IF(ISERROR((BU8/$F8)),"",BU8/$F8) -> 0 | BW8: 395 | BX8: =IF(ISERROR((BW8/$F8)),"",BW8/$F8) -> 0.0010110991 | BY8: 0 | BZ8: =IF(ISERROR((BY8/$F8)),"",BY8/$F8) -> 0 | CA8: 0 | CB8: =IF(ISERROR((CA8/$F8)),"",CA8/$F8) -> 0 | CC8: 7179 | CD8: =IF(ISERROR((CC8/$F8)),"",CC8/$F8) -> 0.018376405 | CE8: 1040 | CF8: =IF(ISERROR((CE8/$F8)),"",CE8/$F8) -> 0.0026621342 | CG8: 0 | CH8: =IF(ISERROR((CG8/$F8)),"",CG8/$F8) -> 0 | CI8: 1298 | CJ8: =IF(ISERROR((CI8/$F8)),"",CI8/$F8) -> 0.0033225483 | CK8: 0 | CL8: =IF(ISERROR((CK8/$F8)),"",CK8/$F8) -> 0 | CM8: 0 | CN8: =IF(ISERROR((CM8/$F8)),"",CM8/$F8) -> 0 | CP8: =IF(ISERROR((CO8/$F8)),"",CO8/$F8) -> 0 | CR8: =IF(ISERROR((CQ8/$F8)),"",CQ8/$F8) -> 0 | CT8: =IF(ISERROR((CS8/$F8)),"",CS8/$F8) -> 0 | CX8: 19714 | CY8: 20 | CZ8: 8566 | DA8: 17 | DB8: 4 | DC8: =B8 -> 土 | DP8: =SUM(DF8:DO8) -> 0 | DQ8: =IF(ISERROR((DP8/F8)),"",DP8/F8) -> 0
A9: 5 | B9: 日 | C9: 27 | D9: 21 | E9: 雨 | F9: 588878 | G9: =IF(SUM($F$5:F9)=0,"",SUM($F$5:F9)) -> 1328618 | H9: =IF(ISERROR(G9/V9),"",(G9/V9)) -> 1.5231135 | I9: {=IF($A10="",$G9/($V9-$U$5+INDIRECT(IF(_xlfn.SHEET()<6,"令和8年"&_xlfn.SHEET()+7&"月","令和9年"&_xlfn.SHEET()-5&"月")&"!$U$5")),$G9/($V10-$U$5))} -> 0.99469642 | J9: =IFERROR(G9/AC9,"") -> 0.78154 | K9: 347 | L9: =IF(ISERROR(K9/W9),"",(K9/W9)) -> 1.5917431 | M9: =IF(ISERROR(F9/K9),"",(F9/K9)) -> 1697.0548 | N9: =IF(ISERROR(M9/X9),"",(M9/X9)) -> 0.75454345 | O9: =IF(ISERROR(F9/P9),"",(F9/P9)) -> 53.87229 | P9: 10931 | Q9: =IF(ISERROR(P9/K9),"",(P9/K9)) -> 31.501441 | R9: 35 | S9: 26 | T9: 晴 | U9: 490307 | V9: =SUM(V8+U9) -> 872304 | W9: 218 | X9: =IF(ISERROR(U9/W9),"",(U9/W9)) -> 2249.1147 | Y9: 192510 | Z9: =SUM(Z8+Y9) -> 939165 | AA9: =IF(ISERROR(V9/Z9),"",(V9/Z9)) -> 0.92880804 | AB9: 550000 | AC9: =AB9+AC8 -> 1700000 | AD9: 76000 | AE9: 138853 | AF9: 8261 | AG9: 0 | AH9: 0 | AI9: 1397 | AJ9: 0 | AK9: 0 | AL9: 22582 | AM9: 0 | AN9: 0 | AR9: =SUM(AD9:AQ9) -> 247093 | AS9: =IF(ISERROR((AR9/F9)),"",AR9/F9) -> 0.41959965 | AT9: =F9-AR9+DW9 -> 341785 | AV9: =A9 -> 5 | AW9: 106050 | AX9: =IF(ISERROR((AW9/$F9)),"",AW9/$F9) -> 0.18008824 | AY9: 2966 | AZ9: =IF(ISERROR((AY9/$F9)),"",AY9/$F9) -> 0.0050366969 | BA9: 214969 | BB9: =IF(ISERROR((BA9/$F9)),"",BA9/$F9) -> 0.36504845 | BC9: 6790 | BD9: =IF(ISERROR((BC9/$F9)),"",BC9/$F9) -> 0.011530402 | BE9: 0 | BF9: =IF(ISERROR((BE9/$F9)),"",BE9/$F9) -> 0 | BG9: 8048 | BH9: =IF(ISERROR((BG9/$F9)),"",BG9/$F9) -> 0.013666668 | BI9: 3086 | BJ9: =IF(ISERROR((BI9/$F9)),"",BI9/$F9) -> 0.0052404743 | BK9: 21834 | BL9: =IF(ISERROR((BK9/$F9)),"",BK9/$F9) -> 0.037077289 | BM9: 130459 | BN9: =IF(ISERROR((BM9/$F9)),"",BM9/$F9) -> 0.22153825 | BO9: 2691 | BP9: =IF(ISERROR((BO9/$F9)),"",BO9/$F9) -> 0.0045697071 | BQ9: 2286 | BR9: =IF(ISERROR((BQ9/$F9)),"",BQ9/$F9) -> 0.0038819586 | BS9: 705 | BT9: =IF(ISERROR((BS9/$F9)),"",BS9/$F9) -> 0.0011971919 | BU9: 0 | BV9: =IF(ISERROR((BU9/$F9)),"",BU9/$F9) -> 0 | BW9: 900 | BX9: =IF(ISERROR((BW9/$F9)),"",BW9/$F9) -> 0.0015283301 | BY9: 0 | BZ9: =IF(ISERROR((BY9/$F9)),"",BY9/$F9) -> 0 | CA9: 0 | CB9: =IF(ISERROR((CA9/$F9)),"",CA9/$F9) -> 0 | CC9: 8532 | CD9: =IF(ISERROR((CC9/$F9)),"",CC9/$F9) -> 0.01448857 | CE9: 1680 | CF9: =IF(ISERROR((CE9/$F9)),"",CE9/$F9) -> 0.0028528829 | CG9: 0 | CH9: =IF(ISERROR((CG9/$F9)),"",CG9/$F9) -> 0 | CI9: 1770 | CJ9: =IF(ISERROR((CI9/$F9)),"",CI9/$F9) -> 0.003005716 | CK9: 0 | CL9: =IF(ISERROR((CK9/$F9)),"",CK9/$F9) -> 0 | CM9: 0 | CN9: =IF(ISERROR((CM9/$F9)),"",CM9/$F9) -> 0 | CP9: =IF(ISERROR((CO9/$F9)),"",CO9/$F9) -> 0 | CR9: =IF(ISERROR((CQ9/$F9)),"",CQ9/$F9) -> 0 | CT9: =IF(ISERROR((CS9/$F9)),"",CS9/$F9) -> 0 | CX9: 31809 | CY9: 32 | CZ9: 4110 | DA9: 10 | DB9: 5 | DC9: =B9 -> 日 | DP9: =SUM(DF9:DO9) -> 0 | DQ9: =IF(ISERROR((DP9/F9)),"",DP9/F9) -> 0
A10: 6 | B10: 月 | C10: 25 | D10: 22 | E10: 雨 | F10: 150303 | G10: =IF(SUM($F$5:F10)=0,"",SUM($F$5:F10)) -> 1478921 | H10: =IF(ISERROR(G10/V10),"",(G10/V10)) -> 1.0231356 | I10: {=IF($A11="",$G10/($V10-$U$5+INDIRECT(IF(_xlfn.SHEET()<6,"令和8年"&_xlfn.SHEET()+7&"月","令和9年"&_xlfn.SHEET()-5&"月")&"!$U$5")),$G10/($V11-$U$5))} -> 1.0097609 | J10: =IFERROR(G10/AC10,"") -> 0.77837947 | K10: 89 | L10: =IF(ISERROR(K10/W10),"",(K10/W10)) -> 0.28990228 | M10: =IF(ISERROR(F10/K10),"",(F10/K10)) -> 1688.7978 | N10: =IF(ISERROR(M10/X10),"",(M10/X10)) -> 0.90454209 | O10: =IF(ISERROR(F10/P10),"",(F10/P10)) -> 81.465041 | P10: 1845 | Q10: =IF(ISERROR(P10/K10),"",(P10/K10)) -> 20.730337 | R10: 35 | S10: 25 | T10: 晴 | U10: 573175 | V10: =SUM(V9+U10) -> 1445479 | W10: 307 | X10: =IF(ISERROR(U10/W10),"",(U10/W10)) -> 1867.0195 | Y10: 527692 | Z10: =SUM(Z9+Y10) -> 1466857 | AA10: =IF(ISERROR(V10/Z10),"",(V10/Z10)) -> 0.98542598 | AB10: 200000 | AC10: =AB10+AC9 -> 1900000 | AD10: 22217 | AE10: 21088 | AF10: 8078 | AG10: 0 | AH10: 0 | AI10: 0 | AJ10: 0 | AK10: 0 | AL10: 0 | AM10: 0 | AN10: 0 | AR10: =SUM(AD10:AQ10) -> 51383 | AS10: =IF(ISERROR((AR10/F10)),"",AR10/F10) -> 0.34186277 | AT10: =F10-AR10+DW10 -> 98920 | AV10: =A10 -> 6 | AW10: 33307 | AX10: =IF(ISERROR((AW10/$F10)),"",AW10/$F10) -> 0.22159904 | AY10: 644 | AZ10: =IF(ISERROR((AY10/$F10)),"",AY10/$F10) -> 0.0042846783 | BA10: 36365 | BB10: =IF(ISERROR((BA10/$F10)),"",BA10/$F10) -> 0.24194461 | BC10: 880 | BD10: =IF(ISERROR((BC10/$F10)),"",BC10/$F10) -> 0.0058548399 | BE10: 0 | BF10: =IF(ISERROR((BE10/$F10)),"",BE10/$F10) -> 0 | BG10: 1691 | BH10: =IF(ISERROR((BG10/$F10)),"",BG10/$F10) -> 0.011250607 | BI10: 3026 | BJ10: =IF(ISERROR((BI10/$F10)),"",BI10/$F10) -> 0.020132665 | BK10: 12599 | BL10: =IF(ISERROR((BK10/$F10)),"",BK10/$F10) -> 0.083824009 | BM10: 35576 | BN10: =IF(ISERROR((BM10/$F10)),"",BM10/$F10) -> 0.23669521 | BO10: 1748 | BP10: =IF(ISERROR((BO10/$F10)),"",BO10/$F10) -> 0.011629841 | BQ10: 514 | BR10: =IF(ISERROR((BQ10/$F10)),"",BQ10/$F10) -> 0.0034197588 | BS10: 135 | BT10: =IF(ISERROR((BS10/$F10)),"",BS10/$F10) -> 0.00089818566 | BU10: 0 | BV10: =IF(ISERROR((BU10/$F10)),"",BU10/$F10) -> 0 | BW10: 195 | BX10: =IF(ISERROR((BW10/$F10)),"",BW10/$F10) -> 0.0012973793 | BY10: 0 | BZ10: =IF(ISERROR((BY10/$F10)),"",BY10/$F10) -> 0 | CA10: 0 | CB10: =IF(ISERROR((CA10/$F10)),"",CA10/$F10) -> 0 | CC10: 2226 | CD10: =IF(ISERROR((CC10/$F10)),"",CC10/$F10) -> 0.014810084 | CE10: 400 | CF10: =IF(ISERROR((CE10/$F10)),"",CE10/$F10) -> 0.0026612909 | CG10: 0 | CH10: =IF(ISERROR((CG10/$F10)),"",CG10/$F10) -> 0 | CI10: 236 | CJ10: =IF(ISERROR((CI10/$F10)),"",CI10/$F10) -> 0.0015701616 | CK10: 0 | CL10: =IF(ISERROR((CK10/$F10)),"",CK10/$F10) -> 0 | CM10: 0 | CN10: =IF(ISERROR((CM10/$F10)),"",CM10/$F10) -> 0 | CP10: =IF(ISERROR((CO10/$F10)),"",CO10/$F10) -> 0 | CR10: =IF(ISERROR((CQ10/$F10)),"",CQ10/$F10) -> 0 | CT10: =IF(ISERROR((CS10/$F10)),"",CS10/$F10) -> 0 | CX10: 1211 | CY10: 6 | CZ10: 5394 | DA10: 3 | DB10: 6 | DC10: =B10 -> 月 | DP10: =SUM(DF10:DO10) -> 0 | DQ10: =IF(ISERROR((DP10/F10)),"",DP10/F10) -> 0
A11: 7 | B11: 火 | C11: 30 | D11: 21 | E11: 曇 | F11: 145759 | G11: =IF(SUM($F$5:F11)=0,"",SUM($F$5:F11)) -> 1624680 | H11: =IF(ISERROR(G11/V11),"",(G11/V11)) -> 1.0319347 | I11: {=IF($A12="",$G11/($V11-$U$5+INDIRECT(IF(_xlfn.SHEET()<6,"令和8年"&_xlfn.SHEET()+7&"月","令和9年"&_xlfn.SHEET()-5&"月")&"!$U$5")),$G11/($V12-$U$5))} -> 0.9817634 | J11: =IFERROR(G11/AC11,"") -> 0.77365714 | K11: 94 | L11: =IF(ISERROR(K11/W11),"",(K11/W11)) -> 1.5666667 | M11: =IF(ISERROR(F11/K11),"",(F11/K11)) -> 1550.6277 | N11: =IF(ISERROR(M11/X11),"",(M11/X11)) -> 0.72165292 | O11: =IF(ISERROR(F11/P11),"",(F11/P11)) -> 67.668988 | P11: 2154 | Q11: =IF(ISERROR(P11/K11),"",(P11/K11)) -> 22.914894 | R11: 35 | S11: 20 | T11: 晴 | U11: 128923 | V11: =SUM(V10+U11) -> 1574402 | W11: 60 | X11: =IF(ISERROR(U11/W11),"",(U11/W11)) -> 2148.7167 | Y11: 647488 | Z11: =SUM(Z10+Y11) -> 2114345 | AA11: =IF(ISERROR(V11/Z11),"",(V11/Z11)) -> 0.74462871 | AB11: 200000 | AC11: =AB11+AC10 -> 2100000 | AD11: 24128 | AE11: 23699 | AF11: 2893 | AG11: 0 | AH11: 1182 | AI11: 1968 | AJ11: 0 | AK11: 0 | AL11: 545 | AM11: 0 | AN11: 0 | AR11: =SUM(AD11:AQ11) -> 54415 | AS11: =IF(ISERROR((AR11/F11)),"",AR11/F11) -> 0.37332172 | AT11: =F11-AR11+DW11 -> 91344 | AV11: =A11 -> 7 | AW11: 19384 | AX11: =IF(ISERROR((AW11/$F11)),"",AW11/$F11) -> 0.13298664 | AY11: 932 | AZ11: =IF(ISERROR((AY11/$F11)),"",AY11/$F11) -> 0.0063941163 | BA11: 36139 | BB11: =IF(ISERROR((BA11/$F11)),"",BA11/$F11) -> 0.24793666 | BC11: 8955 | BD11: =IF(ISERROR((BC11/$F11)),"",BC11/$F11) -> 0.06143703 | BE11: 0 | BF11: =IF(ISERROR((BE11/$F11)),"",BE11/$F11) -> 0 | BG11: 1204 | BH11: =IF(ISERROR((BG11/$F11)),"",BG11/$F11) -> 0.0082602103 | BI11: 1050 | BJ11: =IF(ISERROR((BI11/$F11)),"",BI11/$F11) -> 0.0072036718 | BK11: 35091 | BL11: =IF(ISERROR((BK11/$F11)),"",BK11/$F11) -> 0.24074671 | BM11: 19553 | BN11: =IF(ISERROR((BM11/$F11)),"",BM11/$F11) -> 0.13414609 | BO11: 933 | BP11: =IF(ISERROR((BO11/$F11)),"",BO11/$F11) -> 0.006400977 | BQ11: 901 | BR11: =IF(ISERROR((BQ11/$F11)),"",BQ11/$F11) -> 0.0061814365 | BS11: 120 | BT11: =IF(ISERROR((BS11/$F11)),"",BS11/$F11) -> 0.00082327678 | BU11: 0 | BV11: =IF(ISERROR((BU11/$F11)),"",BU11/$F11) -> 0 | BW11: 390 | BX11: =IF(ISERROR((BW11/$F11)),"",BW11/$F11) -> 0.0026756495 | BY11: 0 | BZ11: =IF(ISERROR((BY11/$F11)),"",BY11/$F11) -> 0 | CA11: 0 | CB11: =IF(ISERROR((CA11/$F11)),"",CA11/$F11) -> 0 | CC11: 810 | CD11: =IF(ISERROR((CC11/$F11)),"",CC11/$F11) -> 0.0055571183 | CE11: 0 | CF11: =IF(ISERROR((CE11/$F11)),"",CE11/$F11) -> 0 | CG11: 0 | CH11: =IF(ISERROR((CG11/$F11)),"",CG11/$F11) -> 0 | CI11: 236 | CJ11: =IF(ISERROR((CI11/$F11)),"",CI11/$F11) -> 0.001619111 | CK11: 0 | CL11: =IF(ISERROR((CK11/$F11)),"",CK11/$F11) -> 0 | CM11: 0 | CN11: =IF(ISERROR((CM11/$F11)),"",CM11/$F11) -> 0 | CP11: =IF(ISERROR((CO11/$F11)),"",CO11/$F11) -> 0 | CR11: =IF(ISERROR((CQ11/$F11)),"",CQ11/$F11) -> 0 | CT11: =IF(ISERROR((CS11/$F11)),"",CS11/$F11) -> 0 | CX11: 5106 | CY11: 15 | CZ11: 7679 | DA11: 18 | DB11: 157 | DC11: =B11 -> 火 | DP11: =SUM(DF11:DO11) -> 0 | DQ11: =IF(ISERROR((DP11/F11)),"",DP11/F11) -> 0
A12: 8 | B12: 水 | C12: 26 | D12: 22 | E12: 曇 | F12: 155805 | G12: =IF(SUM($F$5:F12)=0,"",SUM($F$5:F12)) -> 1780485 | H12: =IF(ISERROR(G12/V12),"",(G12/V12)) -> 1.0089815 | I12: {=IF($A13="",$G12/($V12-$U$5+INDIRECT(IF(_xlfn.SHEET()<6,"令和8年"&_xlfn.SHEET()+7&"月","令和9年"&_xlfn.SHEET()-5&"月")&"!$U$5")),$G12/($V13-$U$5))} -> 0.97104669 | J12: =IFERROR(G12/AC12,"") -> 0.77412391 | K12: 115 | L12: =IF(ISERROR(K12/W12),"",(K12/W12)) -> 1.402439 | M12: =IF(ISERROR(F12/K12),"",(F12/K12)) -> 1354.8261 | N12: =IF(ISERROR(M12/X12),"",(M12/X12)) -> 0.58399518 | O12: =IF(ISERROR(F12/P12),"",(F12/P12)) -> 64.891712 | P12: 2401 | Q12: =IF(ISERROR(P12/K12),"",(P12/K12)) -> 20.878261 | R12: 35 | S12: 27 | T12: 晴 | U12: 190234 | V12: =SUM(V11+U12) -> 1764636 | W12: 82 | X12: =IF(ISERROR(U12/W12),"",(U12/W12)) -> 2319.9268 | Y12: 242006 | Z12: =SUM(Z11+Y12) -> 2356351 | AA12: =IF(ISERROR(V12/Z12),"",(V12/Z12)) -> 0.74888503 | AB12: 200000 | AC12: =AB12+AC11 -> 2300000 | AD12: 31762 | AE12: 41451 | AF12: 9712 | AG12: 584 | AH12: 0 | AI12: 1543 | AJ12: 0 | AK12: 0 | AL12: 0 | AM12: 0 | AN12: 0 | AR12: =SUM(AD12:AQ12) -> 85052 | AS12: =IF(ISERROR((AR12/F12)),"",AR12/F12) -> 0.54588749 | AT12: =F12-AR12+DW12 -> 70753 | AV12: =A12 -> 8 | AW12: 25150 | AX12: =IF(ISERROR((AW12/$F12)),"",AW12/$F12) -> 0.16141972 | AY12: 974 | AZ12: =IF(ISERROR((AY12/$F12)),"",AY12/$F12) -> 0.006251404 | BA12: 50985 | BB12: =IF(ISERROR((BA12/$F12)),"",BA12/$F12) -> 0.32723597 | BC12: 2938 | BD12: =IF(ISERROR((BC12/$F12)),"",BC12/$F12) -> 0.018856904 | BE12: 0 | BF12: =IF(ISERROR((BE12/$F12)),"",BE12/$F12) -> 0 | BG12: 2111 | BH12: =IF(ISERROR((BG12/$F12)),"",BG12/$F12) -> 0.013548988 | BI12: 435 | BJ12: =IF(ISERROR((BI12/$F12)),"",BI12/$F12) -> 0.0027919515 | BK12: 27422 | BL12: =IF(ISERROR((BK12/$F12)),"",BK12/$F12) -> 0.17600205 | BM12: 20014 | BN12: =IF(ISERROR((BM12/$F12)),"",BM12/$F12) -> 0.12845544 | BO12: 338 | BP12: =IF(ISERROR((BO12/$F12)),"",BO12/$F12) -> 0.0021693784 | BQ12: 1164 | BR12: =IF(ISERROR((BQ12/$F12)),"",BQ12/$F12) -> 0.0074708771 | BS12: 415 | BT12: =IF(ISERROR((BS12/$F12)),"",BS12/$F12) -> 0.0026635859 | BU12: 0 | BV12: =IF(ISERROR((BU12/$F12)),"",BU12/$F12) -> 0 | BW12: 400 | BX12: =IF(ISERROR((BW12/$F12)),"",BW12/$F12) -> 0.0025673117 | BY12: 0 | BZ12: =IF(ISERROR((BY12/$F12)),"",BY12/$F12) -> 0 | CA12: 0 | CB12: =IF(ISERROR((CA12/$F12)),"",CA12/$F12) -> 0 | CC12: 5495 | CD12: =IF(ISERROR((CC12/$F12)),"",CC12/$F12) -> 0.035268445 | CE12: 0 | CF12: =IF(ISERROR((CE12/$F12)),"",CE12/$F12) -> 0 | CG12: 0 | CH12: =IF(ISERROR((CG12/$F12)),"",CG12/$F12) -> 0 | CI12: 236 | CJ12: =IF(ISERROR((CI12/$F12)),"",CI12/$F12) -> 0.0015147139 | CK12: 0 | CL12: =IF(ISERROR((CK12/$F12)),"",CK12/$F12) -> 0 | CM12: 0 | CN12: =IF(ISERROR((CM12/$F12)),"",CM12/$F12) -> 0 | CP12: =IF(ISERROR((CO12/$F12)),"",CO12/$F12) -> 0 | CR12: =IF(ISERROR((CQ12/$F12)),"",CQ12/$F12) -> 0 | CT12: =IF(ISERROR((CS12/$F12)),"",CS12/$F12) -> 0 | CX12: 3416 | CY12: 9 | CZ12: 10485 | DA12: 24 | DB12: 8 | DC12: =B12 -> 水 | DP12: =SUM(DF12:DO12) -> 0 | DQ12: =IF(ISERROR((DP12/F12)),"",DP12/F12) -> 0
A13: 9 | B13: 木 | C13: 33 | D13: 22 | E13: 晴れ | F13: 167814 | G13: =IF(SUM($F$5:F13)=0,"",SUM($F$5:F13)) -> 1948299 | H13: =IF(ISERROR(G13/V13),"",(G13/V13)) -> 1.0025466 | I13: {=IF($A14="",$G13/($V13-$U$5+INDIRECT(IF(_xlfn.SHEET()<6,"令和8年"&_xlfn.SHEET()+7&"月","令和9年"&_xlfn.SHEET()-5&"月")&"!$U$5")),$G13/($V14-$U$5))} -> 0.99461114 | J13: =IFERROR(G13/AC13,"") -> 0.7793196 | K13: 66 | L13: =IF(ISERROR(K13/W13),"",(K13/W13)) -> 0.85714286 | M13: =IF(ISERROR(F13/K13),"",(F13/K13)) -> 2542.6364 | N13: =IF(ISERROR(M13/X13),"",(M13/X13)) -> 1.0955101 | O13: =IF(ISERROR(F13/P13),"",(F13/P13)) -> 41.292815 | P13: 4064 | Q13: =IF(ISERROR(P13/K13),"",(P13/K13)) -> 61.575758 | R13: 35 | S13: 25 | T13: 晴のち雨 | U13: 178714 | V13: =SUM(V12+U13) -> 1943350 | W13: 77 | X13: =IF(ISERROR(U13/W13),"",(U13/W13)) -> 2320.961 | Y13: 202267 | Z13: =SUM(Z12+Y13) -> 2558618 | AA13: =IF(ISERROR(V13/Z13),"",(V13/Z13)) -> 0.75953112 | AB13: 200000 | AC13: =AB13+AC12 -> 2500000 | AD13: 3403 | AE13: 8779 | AF13: 23264 | AG13: 0 | AH13: 0 | AI13: 674 | AJ13: 0 | AK13: 0 | AL13: 3079 | AM13: 5074 | AN13: 0 | AR13: =SUM(AD13:AQ13) -> 44273 | AS13: =IF(ISERROR((AR13/F13)),"",AR13/F13) -> 0.26382185 | AT13: =F13-AR13+DW13 -> 123541 | AV13: =A13 -> 9 | AW13: 21982 | AX13: =IF(ISERROR((AW13/$F13)),"",AW13/$F13) -> 0.13099026 | AY13: 724 | AZ13: =IF(ISERROR((AY13/$F13)),"",AY13/$F13) -> 0.0043143004 | BA13: 83114 | BB13: =IF(ISERROR((BA13/$F13)),"",BA13/$F13) -> 0.49527453 | BC13: 970 | BD13: =IF(ISERROR((BC13/$F13)),"",BC13/$F13) -> 0.005780209 | BE13: 0 | BF13: =IF(ISERROR((BE13/$F13)),"",BE13/$F13) -> 0 | BG13: 5079 | BH13: =IF(ISERROR((BG13/$F13)),"",BG13/$F13) -> 0.030265651 | BI13: 1118 | BJ13: =IF(ISERROR((BI13/$F13)),"",BI13/$F13) -> 0.0066621378 | BK13: 1621 | BL13: =IF(ISERROR((BK13/$F13)),"",BK13/$F13) -> 0.009659504 | BM13: 26067 | BN13: =IF(ISERROR((BM13/$F13)),"",BM13/$F13) -> 0.15533269 | BO13: 542 | BP13: =IF(ISERROR((BO13/$F13)),"",BO13/$F13) -> 0.0032297663 | BQ13: 1758 | BR13: =IF(ISERROR((BQ13/$F13)),"",BQ13/$F13) -> 0.010475884 | BS13: 90 | BT13: =IF(ISERROR((BS13/$F13)),"",BS13/$F13) -> 0.00053630806 | BU13: 0 | BV13: =IF(ISERROR((BU13/$F13)),"",BU13/$F13) -> 0 | BW13: 200 | BX13: =IF(ISERROR((BW13/$F13)),"",BW13/$F13) -> 0.0011917957 | BY13: 0 | BZ13: =IF(ISERROR((BY13/$F13)),"",BY13/$F13) -> 0 | CA13: 0 | CB13: =IF(ISERROR((CA13/$F13)),"",CA13/$F13) -> 0 | CC13: 2410 | CD13: =IF(ISERROR((CC13/$F13)),"",CC13/$F13) -> 0.014361138 | CE13: 1920 | CF13: =IF(ISERROR((CE13/$F13)),"",CE13/$F13) -> 0.011441239 | CG13: 0 | CH13: =IF(ISERROR((CG13/$F13)),"",CG13/$F13) -> 0 | CI13: 0 | CJ13: =IF(ISERROR((CI13/$F13)),"",CI13/$F13) -> 0 | CK13: 0 | CL13: =IF(ISERROR((CK13/$F13)),"",CK13/$F13) -> 0 | CM13: 0 | CN13: =IF(ISERROR((CM13/$F13)),"",CM13/$F13) -> 0 | CP13: =IF(ISERROR((CO13/$F13)),"",CO13/$F13) -> 0 | CR13: =IF(ISERROR((CQ13/$F13)),"",CQ13/$F13) -> 0 | CT13: =IF(ISERROR((CS13/$F13)),"",CS13/$F13) -> 0 | CX13: 14308 | CY13: 13 | CZ13: 976 | DA13: 1 | DB13: 9 | DC13: =B13 -> 木 | DP13: =SUM(DF13:DO13) -> 0 | DQ13: =IF(ISERROR((DP13/F13)),"",DP13/F13) -> 0
A14: 10 | B14: 金 | C14: 30 | D14: 23 | E14: 晴 | F14: 149370 | G14: =IF(SUM($F$5:F14)=0,"",SUM($F$5:F14)) -> 2097669 | H14: =IF(ISERROR(G14/V14),"",(G14/V14)) -> 1.0140368 | I14: {=IF($A15="",$G14/($V14-$U$5+INDIRECT(IF(_xlfn.SHEET()<6,"令和8年"&_xlfn.SHEET()+7&"月","令和9年"&_xlfn.SHEET()-5&"月")&"!$U$5")),$G14/($V15-$U$5))} -> 1.0097253 | J14: =IFERROR(G14/AC14,"") -> 0.77691444 | K14: 80 | L14: =IF(ISERROR(K14/W14),"",(K14/W14)) -> 1.0958904 | M14: =IF(ISERROR(F14/K14),"",(F14/K14)) -> 1867.125 | N14: =IF(ISERROR(M14/X14),"",(M14/X14)) -> 1.0879466 | O14: =IF(ISERROR(F14/P14),"",(F14/P14)) -> 43.421512 | P14: 3440 | Q14: =IF(ISERROR(P14/K14),"",(P14/K14)) -> 43 | R14: 35 | S14: 24 | T14: 晴 | U14: 125282 | V14: =SUM(V13+U14) -> 2068632 | W14: 73 | X14: =IF(ISERROR(U14/W14),"",(U14/W14)) -> 1716.1918 | Y14: 262451 | Z14: =SUM(Z13+Y14) -> 2821069 | AA14: =IF(ISERROR(V14/Z14),"",(V14/Z14)) -> 0.73327948 | AB14: 200000 | AC14: =AB14+AC13 -> 2700000 | AD14: 23756 | AE14: 41970 | AF14: 1458 | AG14: 0 | AH14: 0 | AI14: 4437 | AJ14: 0 | AK14: 0 | AL14: 2154 | AM14: 0 | AN14: 0 | AR14: =SUM(AD14:AQ14) -> 73775 | AS14: =IF(ISERROR((AR14/F14)),"",AR14/F14) -> 0.49390775 | AT14: =F14-AR14+DW14 -> 75595 | AV14: =A14 -> 10 | AW14: 26071 | AX14: =IF(ISERROR((AW14/$F14)),"",AW14/$F14) -> 0.17453973 | AY14: 1264 | AZ14: =IF(ISERROR((AY14/$F14)),"",AY14/$F14) -> 0.0084622079 | BA14: 70190 | BB14: =IF(ISERROR((BA14/$F14)),"",BA14/$F14) -> 0.46990694 | BC14: 2122 | BD14: =IF(ISERROR((BC14/$F14)),"",BC14/$F14) -> 0.014206333 | BE14: 0 | BF14: =IF(ISERROR((BE14/$F14)),"",BE14/$F14) -> 0 | BG14: 500 | BH14: =IF(ISERROR((BG14/$F14)),"",BG14/$F14) -> 0.0033473924 | BI14: 1313 | BJ14: =IF(ISERROR((BI14/$F14)),"",BI14/$F14) -> 0.0087902524 | BK14: 1963 | BL14: =IF(ISERROR((BK14/$F14)),"",BK14/$F14) -> 0.013141862 | BM14: 19749 | BN14: =IF(ISERROR((BM14/$F14)),"",BM14/$F14) -> 0.1322153 | BO14: 1641 | BP14: =IF(ISERROR((BO14/$F14)),"",BO14/$F14) -> 0.010986142 | BQ14: 2011 | BR14: =IF(ISERROR((BQ14/$F14)),"",BQ14/$F14) -> 0.013463212 | BS14: 135 | BT14: =IF(ISERROR((BS14/$F14)),"",BS14/$F14) -> 0.00090379594 | BU14: 0 | BV14: =IF(ISERROR((BU14/$F14)),"",BU14/$F14) -> 0 | BW14: 200 | BX14: =IF(ISERROR((BW14/$F14)),"",BW14/$F14) -> 0.001338957 | BY14: 0 | BZ14: =IF(ISERROR((BY14/$F14)),"",BY14/$F14) -> 0 | CA14: 0 | CB14: =IF(ISERROR((CA14/$F14)),"",CA14/$F14) -> 0 | CC14: 1615 | CD14: =IF(ISERROR((CC14/$F14)),"",CC14/$F14) -> 0.010812077 | CE14: 640 | CF14: =IF(ISERROR((CE14/$F14)),"",CE14/$F14) -> 0.0042846622 | CG14: 0 | CH14: =IF(ISERROR((CG14/$F14)),"",CG14/$F14) -> 0 | CI14: 354 | CJ14: =IF(ISERROR((CI14/$F14)),"",CI14/$F14) -> 0.0023699538 | CK14: 0 | CL14: =IF(ISERROR((CK14/$F14)),"",CK14/$F14) -> 0 | CM14: 0 | CN14: =IF(ISERROR((CM14/$F14)),"",CM14/$F14) -> 0 | CP14: =IF(ISERROR((CO14/$F14)),"",CO14/$F14) -> 0 | CR14: =IF(ISERROR((CQ14/$F14)),"",CQ14/$F14) -> 0 | CT14: =IF(ISERROR((CS14/$F14)),"",CS14/$F14) -> 0 | CX14: 3699 | CY14: 9 | CZ14: 11260 | DA14: 27 | DB14: 10 | DC14: =B14 -> 金 | DP14: =SUM(DF14:DO14) -> 0 | DQ14: =IF(ISERROR((DP14/F14)),"",DP14/F14) -> 0
A15: 11 | B15: 土 | C15: 31 | D15: 22 | E15: 晴 | F15: 429003 | G15: =IF(SUM($F$5:F15)=0,"",SUM($F$5:F15)) -> 2526672 | H15: =IF(ISERROR(G15/V15),"",(G15/V15)) -> 1.1551863 | I15: {=IF($A16="",$G15/($V15-$U$5+INDIRECT(IF(_xlfn.SHEET()<6,"令和8年"&_xlfn.SHEET()+7&"月","令和9年"&_xlfn.SHEET()-5&"月")&"!$U$5")),$G15/($V16-$U$5))} -> 1.0386667 | J15: =IFERROR(G15/AC15,"") -> 0.77743754 | K15: 235 | L15: =IF(ISERROR(K15/W15),"",(K15/W15)) -> 3.671875 | M15: =IF(ISERROR(F15/K15),"",(F15/K15)) -> 1825.5447 | N15: =IF(ISERROR(M15/X15),"",(M15/X15)) -> 0.9850338 | O15: =IF(ISERROR(F15/P15),"",(F15/P15)) -> 57.809325 | P15: 7421 | Q15: =IF(ISERROR(P15/K15),"",(P15/K15)) -> 31.578723 | R15: 36 | S15: 25 | T15: 晴のち雨 | U15: 118610 | V15: =SUM(V14+U15) -> 2187242 | W15: 64 | X15: =IF(ISERROR(U15/W15),"",(U15/W15)) -> 1853.2812 | Y15: 206129 | Z15: =SUM(Z14+Y15) -> 3027198 | AA15: =IF(ISERROR(V15/Z15),"",(V15/Z15)) -> 0.72253021 | AB15: 550000 | AC15: =AB15+AC14 -> 3250000 | AD15: 100194 | AE15: 88269 | AF15: 9040 | AG15: 0 | AH15: 0 | AI15: 1251 | AJ15: 461 | AK15: 0 | AL15: 5947 | AM15: 0 | AN15: 0 | AR15: =SUM(AD15:AQ15) -> 205162 | AS15: =IF(ISERROR((AR15/F15)),"",AR15/F15) -> 0.47822976 | AT15: =F15-AR15+DW15 -> 223841 | AV15: =A15 -> 11 | AW15: 81901 | AX15: =IF(ISERROR((AW15/$F15)),"",AW15/$F15) -> 0.19091009 | AY15: 3876 | AZ15: =IF(ISERROR((AY15/$F15)),"",AY15/$F15) -> 0.0090349019 | BA15: 143341 | BB15: =IF(ISERROR((BA15/$F15)),"",BA15/$F15) -> 0.33412587 | BC15: 6349 | BD15: =IF(ISERROR((BC15/$F15)),"",BC15/$F15) -> 0.01479943 | BE15: 0 | BF15: =IF(ISERROR((BE15/$F15)),"",BE15/$F15) -> 0 | BG15: 1928 | BH15: =IF(ISERROR((BG15/$F15)),"",BG15/$F15) -> 0.0044941411 | BI15: 4614 | BJ15: =IF(ISERROR((BI15/$F15)),"",BI15/$F15) -> 0.01075517 | BK15: 14852 | BL15: =IF(ISERROR((BK15/$F15)),"",BK15/$F15) -> 0.034619805 | BM15: 99538 | BN15: =IF(ISERROR((BM15/$F15)),"",BM15/$F15) -> 0.23202169 | BO15: 3954 | BP15: =IF(ISERROR((BO15/$F15)),"",BO15/$F15) -> 0.0092167188 | BQ15: 3912 | BR15: =IF(ISERROR((BQ15/$F15)),"",BQ15/$F15) -> 0.0091188174 | BS15: 595 | BT15: =IF(ISERROR((BS15/$F15)),"",BS15/$F15) -> 0.0013869367 | BU15: 0 | BV15: =IF(ISERROR((BU15/$F15)),"",BU15/$F15) -> 0 | BW15: 1285 | BX15: =IF(ISERROR((BW15/$F15)),"",BW15/$F15) -> 0.002995317 | BY15: 0 | BZ15: =IF(ISERROR((BY15/$F15)),"",BY15/$F15) -> 0 | CA15: 0 | CB15: =IF(ISERROR((CA15/$F15)),"",CA15/$F15) -> 0 | CC15: 5054 | CD15: =IF(ISERROR((CC15/$F15)),"",CC15/$F15) -> 0.011780803 | CE15: 320 | CF15: =IF(ISERROR((CE15/$F15)),"",CE15/$F15) -> 0.00074591553 | CG15: 0 | CH15: =IF(ISERROR((CG15/$F15)),"",CG15/$F15) -> 0 | CI15: 2596 | CJ15: =IF(ISERROR((CI15/$F15)),"",CI15/$F15) -> 0.0060512397 | CK15: 0 | CL15: =IF(ISERROR((CK15/$F15)),"",CK15/$F15) -> 0 | CM15: 0 | CN15: =IF(ISERROR((CM15/$F15)),"",CM15/$F15) -> 0 | CP15: =IF(ISERROR((CO15/$F15)),"",CO15/$F15) -> 0 | CR15: =IF(ISERROR((CQ15/$F15)),"",CQ15/$F15) -> 0 | CT15: =IF(ISERROR((CS15/$F15)),"",CS15/$F15) -> 0 | CX15: 25151 | CY15: 37 | CZ15: 5958 | DA15: 20 | DB15: 11 | DC15: =B15 -> 土 | DP15: =SUM(DF15:DO15) -> 0 | DQ15: =IF(ISERROR((DP15/F15)),"",DP15/F15) -> 0
A16: 12 | B16: 日 | C16: 33 | D16: 24 | E16: 晴 | F16: 632758 | G16: =IF(SUM($F$5:F16)=0,"",SUM($F$5:F16)) -> 3159430 | H16: =IF(ISERROR(G16/V16),"",(G16/V16)) -> 1.2427017 | I16: {=IF($A17="",$G16/($V16-$U$5+INDIRECT(IF(_xlfn.SHEET()<6,"令和8年"&_xlfn.SHEET()+7&"月","令和9年"&_xlfn.SHEET()-5&"月")&"!$U$5")),$G16/($V17-$U$5))} -> 1.0553638 | J16: =IFERROR(G16/AC16,"") -> 0.83142895 | K16: 325 | L16: =IF(ISERROR(K16/W16),"",(K16/W16)) -> 1.7567568 | M16: =IF(ISERROR(F16/K16),"",(F16/K16)) -> 1946.9477 | N16: =IF(ISERROR(M16/X16),"",(M16/X16)) -> 1.0141894 | O16: =IF(ISERROR(F16/P16),"",(F16/P16)) -> 52.598337 | P16: 12030 | Q16: =IF(ISERROR(P16/K16),"",(P16/K16)) -> 37.015385 | R16: 35 | S16: 25 | T16: 晴 | U16: 355146 | V16: =SUM(V15+U16) -> 2542388 | W16: 185 | X16: =IF(ISERROR(U16/W16),"",(U16/W16)) -> 1919.7081 | Y16: 181461 | Z16: =SUM(Z15+Y16) -> 3208659 | AA16: =IF(ISERROR(V16/Z16),"",(V16/Z16)) -> 0.79235219 | AB16: 550000 | AC16: =AB16+AC15 -> 3800000 | AD16: 149533 | AE16: 124812 | AF16: 7185 | AG16: 0 | AH16: 962 | AI16: 6445 | AJ16: 2123 | AK16: 0 | AL16: 10233 | AM16: 1976 | AN16: 0 | AR16: =SUM(AD16:AQ16) -> 303269 | AS16: =IF(ISERROR((AR16/F16)),"",AR16/F16) -> 0.47928118 | AT16: =F16-AR16+DW16 -> 329489 | AV16: =A16 -> 12 | AW16: 138741 | AX16: =IF(ISERROR((AW16/$F16)),"",AW16/$F16) -> 0.21926392 | AY16: 7636 | AZ16: =IF(ISERROR((AY16/$F16)),"",AY16/$F16) -> 0.012067805 | BA16: 227055 | BB16: =IF(ISERROR((BA16/$F16)),"",BA16/$F16) -> 0.35883387 | BC16: 5562 | BD16: =IF(ISERROR((BC16/$F16)),"",BC16/$F16) -> 0.0087900904 | BE16: 0 | BF16: =IF(ISERROR((BE16/$F16)),"",BE16/$F16) -> 0 | BG16: 5614 | BH16: =IF(ISERROR((BG16/$F16)),"",BG16/$F16) -> 0.0088722703 | BI16: 4314 | BJ16: =IF(ISERROR((BI16/$F16)),"",BI16/$F16) -> 0.0068177724 | BK16: 24447 | BL16: =IF(ISERROR((BK16/$F16)),"",BK16/$F16) -> 0.038635624 | BM16: 109704 | BN16: =IF(ISERROR((BM16/$F16)),"",BM16/$F16) -> 0.17337434 | BO16: 2891 | BP16: =IF(ISERROR((BO16/$F16)),"",BO16/$F16) -> 0.0045688873 | BQ16: 5551 | BR16: =IF(ISERROR((BQ16/$F16)),"",BQ16/$F16) -> 0.0087727062 | BS16: 830 | BT16: =IF(ISERROR((BS16/$F16)),"",BS16/$F16) -> 0.0013117179 | BU16: 0 | BV16: =IF(ISERROR((BU16/$F16)),"",BU16/$F16) -> 0 | BW16: 2655 | BX16: =IF(ISERROR((BW16/$F16)),"",BW16/$F16) -> 0.0041959169 | BY16: 0 | BZ16: =IF(ISERROR((BY16/$F16)),"",BY16/$F16) -> 0 | CA16: 0 | CB16: =IF(ISERROR((CA16/$F16)),"",CA16/$F16) -> 0 | CC16: 8442 | CD16: =IF(ISERROR((CC16/$F16)),"",CC16/$F16) -> 0.013341593 | CE16: 1280 | CF16: =IF(ISERROR((CE16/$F16)),"",CE16/$F16) -> 0.0020228903 | CG16: 0 | CH16: =IF(ISERROR((CG16/$F16)),"",CG16/$F16) -> 0 | CI16: 4484 | CJ16: =IF(ISERROR((CI16/$F16)),"",CI16/$F16) -> 0.0070864375 | CK16: 0 | CL16: =IF(ISERROR((CK16/$F16)),"",CK16/$F16) -> 0 | CM16: 0 | CN16: =IF(ISERROR((CM16/$F16)),"",CM16/$F16) -> 0 | CP16: =IF(ISERROR((CO16/$F16)),"",CO16/$F16) -> 0 | CR16: =IF(ISERROR((CQ16/$F16)),"",CQ16/$F16) -> 0 | CT16: =IF(ISERROR((CS16/$F16)),"",CS16/$F16) -> 0 | CX16: 5719 | CY16: 13 | CZ16: 17298 | DA16: 34 | DB16: 12 | DC16: =B16 -> 日 | DP16: =SUM(DF16:DO16) -> 0 | DQ16: =IF(ISERROR((DP16/F16)),"",DP16/F16) -> 0
A17: 13 | B17: 月 | G17: =IF(SUM($F$5:F17)=0,"",SUM($F$5:F17)) -> 3159430 | H17: =IF(ISERROR(G17/V17),"",(G17/V17)) -> 1.0180331 | I17: {=IF($A18="",$G17/($V17-$U$5+INDIRECT(IF(_xlfn.SHEET()<6,"令和8年"&_xlfn.SHEET()+7&"月","令和9年"&_xlfn.SHEET()-5&"月")&"!$U$5")),$G17/($V18-$U$5))} -> 1.0214689 | J17: =IFERROR(G17/AC17,"") -> 0.7898575 | L17: =IF(ISERROR(K17/W17),"",(K17/W17)) -> 0 | M17: =IF(ISERROR(F17/K17),"",(F17/K17)) | N17: =IF(ISERROR(M17/X17),"",(M17/X17)) | O17: =IF(ISERROR(F17/P17),"",(F17/P17)) | Q17: =IF(ISERROR(P17/K17),"",(P17/K17)) | R17: 36 | S17: 26 | T17: 晴 | U17: 561077 | V17: =SUM(V16+U17) -> 3103465 | W17: 260 | X17: =IF(ISERROR(U17/W17),"",(U17/W17)) -> 2157.9885 | Y17: 731687 | Z17: =SUM(Z16+Y17) -> 3940346 | AA17: =IF(ISERROR(V17/Z17),"",(V17/Z17)) -> 0.78761231 | AB17: 200000 | AC17: =AB17+AC16 -> 4000000 | AR17: =SUM(AD17:AQ17) -> 0 | AS17: =IF(ISERROR((AR17/F17)),"",AR17/F17) | AT17: =F17-AR17+DW17 -> 0 | AV17: =A17 -> 13 | AX17: =IF(ISERROR((AW17/$F17)),"",AW17/$F17) | AZ17: =IF(ISERROR((AY17/$F17)),"",AY17/$F17) | BB17: =IF(ISERROR((BA17/$F17)),"",BA17/$F17) | BD17: =IF(ISERROR((BC17/$F17)),"",BC17/$F17) | BF17: =IF(ISERROR((BE17/$F17)),"",BE17/$F17) | BH17: =IF(ISERROR((BG17/$F17)),"",BG17/$F17) | BJ17: =IF(ISERROR((BI17/$F17)),"",BI17/$F17) | BL17: =IF(ISERROR((BK17/$F17)),"",BK17/$F17) | BN17: =IF(ISERROR((BM17/$F17)),"",BM17/$F17) | BP17: =IF(ISERROR((BO17/$F17)),"",BO17/$F17) | BR17: =IF(ISERROR((BQ17/$F17)),"",BQ17/$F17) | BT17: =IF(ISERROR((BS17/$F17)),"",BS17/$F17) | BV17: =IF(ISERROR((BU17/$F17)),"",BU17/$F17) | BX17: =IF(ISERROR((BW17/$F17)),"",BW17/$F17) | BZ17: =IF(ISERROR((BY17/$F17)),"",BY17/$F17) | CB17: =IF(ISERROR((CA17/$F17)),"",CA17/$F17) | CD17: =IF(ISERROR((CC17/$F17)),"",CC17/$F17) | CF17: =IF(ISERROR((CE17/$F17)),"",CE17/$F17) | CH17: =IF(ISERROR((CG17/$F17)),"",CG17/$F17) | CJ17: =IF(ISERROR((CI17/$F17)),"",CI17/$F17) | CL17: =IF(ISERROR((CK17/$F17)),"",CK17/$F17) | CN17: =IF(ISERROR((CM17/$F17)),"",CM17/$F17) | CP17: =IF(ISERROR((CO17/$F17)),"",CO17/$F17) | CR17: =IF(ISERROR((CQ17/$F17)),"",CQ17/$F17) | CT17: =IF(ISERROR((CS17/$F17)),"",CS17/$F17) | DB17: 13 | DC17: =B17 -> 月 | DP17: =SUM(DF17:DO17) -> 0 | DQ17: =IF(ISERROR((DP17/F17)),"",DP17/F17)
A18: 14 | B18: 火 | G18: =IF(SUM($F$5:F18)=0,"",SUM($F$5:F18)) -> 3159430 | H18: =IF(ISERROR(G18/V18),"",(G18/V18)) -> 0.9864578 | I18: {=IF($A19="",$G18/($V18-$U$5+INDIRECT(IF(_xlfn.SHEET()<6,"令和8年"&_xlfn.SHEET()+7&"月","令和9年"&_xlfn.SHEET()-5&"月")&"!$U$5")),$G18/($V19-$U$5))} -> 0.96741193 | J18: =IFERROR(G18/AC18,"") -> 0.75224524 | L18: =IF(ISERROR(K18/W18),"",(K18/W18)) -> 0 | M18: =IF(ISERROR(F18/K18),"",(F18/K18)) | N18: =IF(ISERROR(M18/X18),"",(M18/X18)) | O18: =IF(ISERROR(F18/P18),"",(F18/P18)) | Q18: =IF(ISERROR(P18/K18),"",(P18/K18)) | R18: 35 | S18: 25 | T18: 晴/雨 | U18: 99338 | V18: =SUM(V17+U18) -> 3202803 | W18: 81 | X18: =IF(ISERROR(U18/W18),"",(U18/W18)) -> 1226.3951 | Y18: 1135665 | Z18: =SUM(Z17+Y18) -> 5076011 | AA18: =IF(ISERROR(V18/Z18),"",(V18/Z18)) -> 0.63096849 | AB18: 200000 | AC18: =AB18+AC17 -> 4200000 | AR18: =SUM(AD18:AQ18) -> 0 | AS18: =IF(ISERROR((AR18/F18)),"",AR18/F18) | AT18: =F18-AR18+DW18 -> 0 | AV18: =A18 -> 14 | AX18: =IF(ISERROR((AW18/$F18)),"",AW18/$F18) | AZ18: =IF(ISERROR((AY18/$F18)),"",AY18/$F18) | BB18: =IF(ISERROR((BA18/$F18)),"",BA18/$F18) | BD18: =IF(ISERROR((BC18/$F18)),"",BC18/$F18) | BF18: =IF(ISERROR((BE18/$F18)),"",BE18/$F18) | BH18: =IF(ISERROR((BG18/$F18)),"",BG18/$F18) | BJ18: =IF(ISERROR((BI18/$F18)),"",BI18/$F18) | BL18: =IF(ISERROR((BK18/$F18)),"",BK18/$F18) | BN18: =IF(ISERROR((BM18/$F18)),"",BM18/$F18) | BP18: =IF(ISERROR((BO18/$F18)),"",BO18/$F18) | BR18: =IF(ISERROR((BQ18/$F18)),"",BQ18/$F18) | BT18: =IF(ISERROR((BS18/$F18)),"",BS18/$F18) | BV18: =IF(ISERROR((BU18/$F18)),"",BU18/$F18) | BX18: =IF(ISERROR((BW18/$F18)),"",BW18/$F18) | BZ18: =IF(ISERROR((BY18/$F18)),"",BY18/$F18) | CB18: =IF(ISERROR((CA18/$F18)),"",CA18/$F18) | CD18: =IF(ISERROR((CC18/$F18)),"",CC18/$F18) | CF18: =IF(ISERROR((CE18/$F18)),"",CE18/$F18) | CH18: =IF(ISERROR((CG18/$F18)),"",CG18/$F18) | CJ18: =IF(ISERROR((CI18/$F18)),"",CI18/$F18) | CL18: =IF(ISERROR((CK18/$F18)),"",CK18/$F18) | CN18: =IF(ISERROR((CM18/$F18)),"",CM18/$F18) | CP18: =IF(ISERROR((CO18/$F18)),"",CO18/$F18) | CR18: =IF(ISERROR((CQ18/$F18)),"",CQ18/$F18) | CT18: =IF(ISERROR((CS18/$F18)),"",CS18/$F18) | DB18: 14 | DC18: =B18 -> 火 | DP18: =SUM(DF18:DO18) -> 0 | DQ18: =IF(ISERROR((DP18/F18)),"",DP18/F18)
A19: 15 | B19: 水 | G19: =IF(SUM($F$5:F19)=0,"",SUM($F$5:F19)) -> 3159430 | H19: =IF(ISERROR(G19/V19),"",(G19/V19)) -> 0.93595131 | I19: {=IF($A20="",$G19/($V19-$U$5+INDIRECT(IF(_xlfn.SHEET()<6,"令和8年"&_xlfn.SHEET()+7&"月","令和9年"&_xlfn.SHEET()-5&"月")&"!$U$5")),$G19/($V20-$U$5))} -> 0.91309364 | J19: =IFERROR(G19/AC19,"") -> 0.71805227 | L19: =IF(ISERROR(K19/W19),"",(K19/W19)) -> 0 | M19: =IF(ISERROR(F19/K19),"",(F19/K19)) | N19: =IF(ISERROR(M19/X19),"",(M19/X19)) | O19: =IF(ISERROR(F19/P19),"",(F19/P19)) | Q19: =IF(ISERROR(P19/K19),"",(P19/K19)) | R19: 37 | S19: 26 | T19: 晴 | U19: 172832 | V19: =SUM(V18+U19) -> 3375635 | W19: 98 | X19: =IF(ISERROR(U19/W19),"",(U19/W19)) -> 1763.5918 | Y19: 672231 | Z19: =SUM(Z18+Y19) -> 5748242 | AA19: =IF(ISERROR(V19/Z19),"",(V19/Z19)) -> 0.5872465 | AB19: 200000 | AC19: =AB19+AC18 -> 4400000 | AR19: =SUM(AD19:AQ19) -> 0 | AS19: =IF(ISERROR((AR19/F19)),"",AR19/F19) | AT19: =F19-AR19+DW19 -> 0 | AV19: =A19 -> 15 | AX19: =IF(ISERROR((AW19/$F19)),"",AW19/$F19) | AZ19: =IF(ISERROR((AY19/$F19)),"",AY19/$F19) | BB19: =IF(ISERROR((BA19/$F19)),"",BA19/$F19) | BD19: =IF(ISERROR((BC19/$F19)),"",BC19/$F19) | BF19: =IF(ISERROR((BE19/$F19)),"",BE19/$F19) | BH19: =IF(ISERROR((BG19/$F19)),"",BG19/$F19) | BJ19: =IF(ISERROR((BI19/$F19)),"",BI19/$F19) | BL19: =IF(ISERROR((BK19/$F19)),"",BK19/$F19) | BN19: =IF(ISERROR((BM19/$F19)),"",BM19/$F19) | BP19: =IF(ISERROR((BO19/$F19)),"",BO19/$F19) | BR19: =IF(ISERROR((BQ19/$F19)),"",BQ19/$F19) | BT19: =IF(ISERROR((BS19/$F19)),"",BS19/$F19) | BV19: =IF(ISERROR((BU19/$F19)),"",BU19/$F19) | BX19: =IF(ISERROR((BW19/$F19)),"",BW19/$F19) | BZ19: =IF(ISERROR((BY19/$F19)),"",BY19/$F19) | CB19: =IF(ISERROR((CA19/$F19)),"",CA19/$F19) | CD19: =IF(ISERROR((CC19/$F19)),"",CC19/$F19) | CF19: =IF(ISERROR((CE19/$F19)),"",CE19/$F19) | CH19: =IF(ISERROR((CG19/$F19)),"",CG19/$F19) | CJ19: =IF(ISERROR((CI19/$F19)),"",CI19/$F19) | CL19: =IF(ISERROR((CK19/$F19)),"",CK19/$F19) | CN19: =IF(ISERROR((CM19/$F19)),"",CM19/$F19) | CP19: =IF(ISERROR((CO19/$F19)),"",CO19/$F19) | CR19: =IF(ISERROR((CQ19/$F19)),"",CQ19/$F19) | CT19: =IF(ISERROR((CS19/$F19)),"",CS19/$F19) | DB19: 15 | DC19: =B19 -> 水 | DP19: =SUM(DF19:DO19) -> 0 | DQ19: =IF(ISERROR((DP19/F19)),"",DP19/F19)
A20: 16 | B20: 木 | G20: =IF(SUM($F$5:F20)=0,"",SUM($F$5:F20)) -> 3159430 | H20: =IF(ISERROR(G20/V20),"",(G20/V20)) -> 0.88501547 | I20: {=IF($A21="",$G20/($V20-$U$5+INDIRECT(IF(_xlfn.SHEET()<6,"令和8年"&_xlfn.SHEET()+7&"月","令和9年"&_xlfn.SHEET()-5&"月")&"!$U$5")),$G20/($V21-$U$5))} -> 0.85582723 | J20: =IFERROR(G20/AC20,"") -> 0.68683261 | L20: =IF(ISERROR(K20/W20),"",(K20/W20)) -> 0 | M20: =IF(ISERROR(F20/K20),"",(F20/K20)) | N20: =IF(ISERROR(M20/X20),"",(M20/X20)) | O20: =IF(ISERROR(F20/P20),"",(F20/P20)) | Q20: =IF(ISERROR(P20/K20),"",(P20/K20)) | R20: 30 | S20: 25 | T20: 晴のち雨 | U20: 194280 | V20: =SUM(V19+U20) -> 3569915 | W20: 74 | X20: =IF(ISERROR(U20/W20),"",(U20/W20)) -> 2625.4054 | Y20: 313296 | Z20: =SUM(Z19+Y20) -> 6061538 | AA20: =IF(ISERROR(V20/Z20),"",(V20/Z20)) -> 0.58894541 | AB20: 200000 | AC20: =AB20+AC19 -> 4600000 | AR20: =SUM(AD20:AQ20) -> 0 | AS20: =IF(ISERROR((AR20/F20)),"",AR20/F20) | AT20: =F20-AR20+DW20 -> 0 | AV20: =A20 -> 16 | AX20: =IF(ISERROR((AW20/$F20)),"",AW20/$F20) | AZ20: =IF(ISERROR((AY20/$F20)),"",AY20/$F20) | BB20: =IF(ISERROR((BA20/$F20)),"",BA20/$F20) | BD20: =IF(ISERROR((BC20/$F20)),"",BC20/$F20) | BF20: =IF(ISERROR((BE20/$F20)),"",BE20/$F20) | BH20: =IF(ISERROR((BG20/$F20)),"",BG20/$F20) | BJ20: =IF(ISERROR((BI20/$F20)),"",BI20/$F20) | BL20: =IF(ISERROR((BK20/$F20)),"",BK20/$F20) | BN20: =IF(ISERROR((BM20/$F20)),"",BM20/$F20) | BP20: =IF(ISERROR((BO20/$F20)),"",BO20/$F20) | BR20: =IF(ISERROR((BQ20/$F20)),"",BQ20/$F20) | BT20: =IF(ISERROR((BS20/$F20)),"",BS20/$F20) | BV20: =IF(ISERROR((BU20/$F20)),"",BU20/$F20) | BX20: =IF(ISERROR((BW20/$F20)),"",BW20/$F20) | BZ20: =IF(ISERROR((BY20/$F20)),"",BY20/$F20) | CB20: =IF(ISERROR((CA20/$F20)),"",CA20/$F20) | CD20: =IF(ISERROR((CC20/$F20)),"",CC20/$F20) | CF20: =IF(ISERROR((CE20/$F20)),"",CE20/$F20) | CH20: =IF(ISERROR((CG20/$F20)),"",CG20/$F20) | CJ20: =IF(ISERROR((CI20/$F20)),"",CI20/$F20) | CL20: =IF(ISERROR((CK20/$F20)),"",CK20/$F20) | CN20: =IF(ISERROR((CM20/$F20)),"",CM20/$F20) | CP20: =IF(ISERROR((CO20/$F20)),"",CO20/$F20) | CR20: =IF(ISERROR((CQ20/$F20)),"",CQ20/$F20) | CT20: =IF(ISERROR((CS20/$F20)),"",CS20/$F20) | DB20: 16 | DC20: =B20 -> 木 | DP20: =SUM(DF20:DO20) -> 0 | DQ20: =IF(ISERROR((DP20/F20)),"",DP20/F20)
A21: 17 | B21: 金 | G21: =IF(SUM($F$5:F21)=0,"",SUM($F$5:F21)) -> 3159430 | H21: =IF(ISERROR(G21/V21),"",(G21/V21)) -> 0.83111291 | I21: {=IF($A22="",$G21/($V21-$U$5+INDIRECT(IF(_xlfn.SHEET()<6,"令和8年"&_xlfn.SHEET()+7&"月","令和9年"&_xlfn.SHEET()-5&"月")&"!$U$5")),$G21/($V22-$U$5))} -> 0.8088878 | J21: =IFERROR(G21/AC21,"") -> 0.65821458 | L21: =IF(ISERROR(K21/W21),"",(K21/W21)) -> 0 | M21: =IF(ISERROR(F21/K21),"",(F21/K21)) | N21: =IF(ISERROR(M21/X21),"",(M21/X21)) | O21: =IF(ISERROR(F21/P21),"",(F21/P21)) | Q21: =IF(ISERROR(P21/K21),"",(P21/K21)) | R21: 33 | S21: 25 | T21: 雨 | U21: 231530 | V21: =SUM(V20+U21) -> 3801445 | W21: 99 | X21: =IF(ISERROR(U21/W21),"",(U21/W21)) -> 2338.6869 | Y21: 235048 | Z21: =SUM(Z20+Y21) -> 6296586 | AA21: =IF(ISERROR(V21/Z21),"",(V21/Z21)) -> 0.60373113 | AB21: 200000 | AC21: =AB21+AC20 -> 4800000 | AR21: =SUM(AD21:AQ21) -> 0 | AS21: =IF(ISERROR((AR21/F21)),"",AR21/F21) | AT21: =F21-AR21+DW21 -> 0 | AV21: =A21 -> 17 | AX21: =IF(ISERROR((AW21/$F21)),"",AW21/$F21) | AZ21: =IF(ISERROR((AY21/$F21)),"",AY21/$F21) | BB21: =IF(ISERROR((BA21/$F21)),"",BA21/$F21) | BD21: =IF(ISERROR((BC21/$F21)),"",BC21/$F21) | BF21: =IF(ISERROR((BE21/$F21)),"",BE21/$F21) | BH21: =IF(ISERROR((BG21/$F21)),"",BG21/$F21) | BJ21: =IF(ISERROR((BI21/$F21)),"",BI21/$F21) | BL21: =IF(ISERROR((BK21/$F21)),"",BK21/$F21) | BN21: =IF(ISERROR((BM21/$F21)),"",BM21/$F21) | BP21: =IF(ISERROR((BO21/$F21)),"",BO21/$F21) | BR21: =IF(ISERROR((BQ21/$F21)),"",BQ21/$F21) | BT21: =IF(ISERROR((BS21/$F21)),"",BS21/$F21) | BV21: =IF(ISERROR((BU21/$F21)),"",BU21/$F21) | BX21: =IF(ISERROR((BW21/$F21)),"",BW21/$F21) | BZ21: =IF(ISERROR((BY21/$F21)),"",BY21/$F21) | CB21: =IF(ISERROR((CA21/$F21)),"",CA21/$F21) | CD21: =IF(ISERROR((CC21/$F21)),"",CC21/$F21) | CF21: =IF(ISERROR((CE21/$F21)),"",CE21/$F21) | CH21: =IF(ISERROR((CG21/$F21)),"",CG21/$F21) | CJ21: =IF(ISERROR((CI21/$F21)),"",CI21/$F21) | CL21: =IF(ISERROR((CK21/$F21)),"",CK21/$F21) | CN21: =IF(ISERROR((CM21/$F21)),"",CM21/$F21) | CP21: =IF(ISERROR((CO21/$F21)),"",CO21/$F21) | CR21: =IF(ISERROR((CQ21/$F21)),"",CQ21/$F21) | CT21: =IF(ISERROR((CS21/$F21)),"",CS21/$F21) | DB21: 17 | DC21: =B21 -> 金 | DP21: =SUM(DF21:DO21) -> 0 | DQ21: =IF(ISERROR((DP21/F21)),"",DP21/F21)
A22: 18 | B22: 土 | G22: =IF(SUM($F$5:F22)=0,"",SUM($F$5:F22)) -> 3159430 | H22: =IF(ISERROR(G22/V22),"",(G22/V22)) -> 0.78677511 | I22: {=IF($A23="",$G22/($V22-$U$5+INDIRECT(IF(_xlfn.SHEET()<6,"令和8年"&_xlfn.SHEET()+7&"月","令和9年"&_xlfn.SHEET()-5&"月")&"!$U$5")),$G22/($V23-$U$5))} -> 0.71342973 | J22: =IFERROR(G22/AC22,"") -> 0.59054766 | L22: =IF(ISERROR(K22/W22),"",(K22/W22)) -> 0 | M22: =IF(ISERROR(F22/K22),"",(F22/K22)) | N22: =IF(ISERROR(M22/X22),"",(M22/X22)) | O22: =IF(ISERROR(F22/P22),"",(F22/P22)) | Q22: =IF(ISERROR(P22/K22),"",(P22/K22)) | R22: 34 | S22: 26 | T22: 晴時々雨 | U22: 214226 | V22: =SUM(V21+U22) -> 4015671 | W22: 78 | X22: =IF(ISERROR(U22/W22),"",(U22/W22)) -> 2746.4872 | Y22: 282999 | Z22: =SUM(Z21+Y22) -> 6579585 | AA22: =IF(ISERROR(V22/Z22),"",(V22/Z22)) -> 0.61032284 | AB22: 550000 | AC22: =AB22+AC21 -> 5350000 | AR22: =SUM(AD22:AQ22) -> 0 | AS22: =IF(ISERROR((AR22/F22)),"",AR22/F22) | AT22: =F22-AR22+DW22 -> 0 | AV22: =A22 -> 18 | AX22: =IF(ISERROR((AW22/$F22)),"",AW22/$F22) | AZ22: =IF(ISERROR((AY22/$F22)),"",AY22/$F22) | BB22: =IF(ISERROR((BA22/$F22)),"",BA22/$F22) | BD22: =IF(ISERROR((BC22/$F22)),"",BC22/$F22) | BF22: =IF(ISERROR((BE22/$F22)),"",BE22/$F22) | BH22: =IF(ISERROR((BG22/$F22)),"",BG22/$F22) | BJ22: =IF(ISERROR((BI22/$F22)),"",BI22/$F22) | BL22: =IF(ISERROR((BK22/$F22)),"",BK22/$F22) | BN22: =IF(ISERROR((BM22/$F22)),"",BM22/$F22) | BP22: =IF(ISERROR((BO22/$F22)),"",BO22/$F22) | BR22: =IF(ISERROR((BQ22/$F22)),"",BQ22/$F22) | BT22: =IF(ISERROR((BS22/$F22)),"",BS22/$F22) | BV22: =IF(ISERROR((BU22/$F22)),"",BU22/$F22) | BX22: =IF(ISERROR((BW22/$F22)),"",BW22/$F22) | BZ22: =IF(ISERROR((BY22/$F22)),"",BY22/$F22) | CB22: =IF(ISERROR((CA22/$F22)),"",CA22/$F22) | CD22: =IF(ISERROR((CC22/$F22)),"",CC22/$F22) | CF22: =IF(ISERROR((CE22/$F22)),"",CE22/$F22) | CH22: =IF(ISERROR((CG22/$F22)),"",CG22/$F22) | CJ22: =IF(ISERROR((CI22/$F22)),"",CI22/$F22) | CL22: =IF(ISERROR((CK22/$F22)),"",CK22/$F22) | CN22: =IF(ISERROR((CM22/$F22)),"",CM22/$F22) | CP22: =IF(ISERROR((CO22/$F22)),"",CO22/$F22) | CR22: =IF(ISERROR((CQ22/$F22)),"",CQ22/$F22) | CT22: =IF(ISERROR((CS22/$F22)),"",CS22/$F22) | DB22: 18 | DC22: =B22 -> 土 | DP22: =SUM(DF22:DO22) -> 0 | DQ22: =IF(ISERROR((DP22/F22)),"",DP22/F22)
A23: 19 | B23: 日 | G23: =IF(SUM($F$5:F23)=0,"",SUM($F$5:F23)) -> 3159430 | H23: =IF(ISERROR(G23/V23),"",(G23/V23)) -> 0.69617252 | I23: {=IF($A24="",$G23/($V23-$U$5+INDIRECT(IF(_xlfn.SHEET()<6,"令和8年"&_xlfn.SHEET()+7&"月","令和9年"&_xlfn.SHEET()-5&"月")&"!$U$5")),$G23/($V24-$U$5))} -> 0.62482399 | J23: =IFERROR(G23/AC23,"") -> 0.53549661 | L23: =IF(ISERROR(K23/W23),"",(K23/W23)) -> 0 | M23: =IF(ISERROR(F23/K23),"",(F23/K23)) | N23: =IF(ISERROR(M23/X23),"",(M23/X23)) | O23: =IF(ISERROR(F23/P23),"",(F23/P23)) | Q23: =IF(ISERROR(P23/K23),"",(P23/K23)) | R23: 35 | S23: 26 | T23: 晴時々雨 | U23: 522615 | V23: =SUM(V22+U23) -> 4538286 | W23: 258 | X23: =IF(ISERROR(U23/W23),"",(U23/W23)) -> 2025.6395 | Y23: 242441 | Z23: =SUM(Z22+Y23) -> 6822026 | AA23: =IF(ISERROR(V23/Z23),"",(V23/Z23)) -> 0.66524021 | AB23: 550000 | AC23: =AB23+AC22 -> 5900000 | AR23: =SUM(AD23:AQ23) -> 0 | AS23: =IF(ISERROR((AR23/F23)),"",AR23/F23) | AT23: =F23-AR23+DW23 -> 0 | AV23: =A23 -> 19 | AX23: =IF(ISERROR((AW23/$F23)),"",AW23/$F23) | AZ23: =IF(ISERROR((AY23/$F23)),"",AY23/$F23) | BB23: =IF(ISERROR((BA23/$F23)),"",BA23/$F23) | BD23: =IF(ISERROR((BC23/$F23)),"",BC23/$F23) | BF23: =IF(ISERROR((BE23/$F23)),"",BE23/$F23) | BH23: =IF(ISERROR((BG23/$F23)),"",BG23/$F23) | BJ23: =IF(ISERROR((BI23/$F23)),"",BI23/$F23) | BL23: =IF(ISERROR((BK23/$F23)),"",BK23/$F23) | BN23: =IF(ISERROR((BM23/$F23)),"",BM23/$F23) | BP23: =IF(ISERROR((BO23/$F23)),"",BO23/$F23) | BR23: =IF(ISERROR((BQ23/$F23)),"",BQ23/$F23) | BT23: =IF(ISERROR((BS23/$F23)),"",BS23/$F23) | BV23: =IF(ISERROR((BU23/$F23)),"",BU23/$F23) | BX23: =IF(ISERROR((BW23/$F23)),"",BW23/$F23) | BZ23: =IF(ISERROR((BY23/$F23)),"",BY23/$F23) | CB23: =IF(ISERROR((CA23/$F23)),"",CA23/$F23) | CD23: =IF(ISERROR((CC23/$F23)),"",CC23/$F23) | CF23: =IF(ISERROR((CE23/$F23)),"",CE23/$F23) | CH23: =IF(ISERROR((CG23/$F23)),"",CG23/$F23) | CJ23: =IF(ISERROR((CI23/$F23)),"",CI23/$F23) | CL23: =IF(ISERROR((CK23/$F23)),"",CK23/$F23) | CN23: =IF(ISERROR((CM23/$F23)),"",CM23/$F23) | CP23: =IF(ISERROR((CO23/$F23)),"",CO23/$F23) | CR23: =IF(ISERROR((CQ23/$F23)),"",CQ23/$F23) | CT23: =IF(ISERROR((CS23/$F23)),"",CS23/$F23) | DB23: 19 | DC23: =B23 -> 日 | DP23: =SUM(DF23:DO23) -> 0 | DQ23: =IF(ISERROR((DP23/F23)),"",DP23/F23)
A24: 20 | B24: 月 | G24: =IF(SUM($F$5:F24)=0,"",SUM($F$5:F24)) -> 3159430 | H24: =IF(ISERROR(G24/V24),"",(G24/V24)) -> 0.61154728 | I24: {=IF($A25="",$G24/($V24-$U$5+INDIRECT(IF(_xlfn.SHEET()<6,"令和8年"&_xlfn.SHEET()+7&"月","令和9年"&_xlfn.SHEET()-5&"月")&"!$U$5")),$G24/($V25-$U$5))} -> 0.55489528 | J24: =IFERROR(G24/AC24,"") -> 0.49366094 | L24: =IF(ISERROR(K24/W24),"",(K24/W24)) -> 0 | M24: =IF(ISERROR(F24/K24),"",(F24/K24)) | N24: =IF(ISERROR(M24/X24),"",(M24/X24)) | O24: =IF(ISERROR(F24/P24),"",(F24/P24)) | Q24: =IF(ISERROR(P24/K24),"",(P24/K24)) | R24: 36 | S24: 26 | T24: 晴 | U24: 628003 | V24: =SUM(V23+U24) -> 5166289 | W24: 343 | X24: =IF(ISERROR(U24/W24),"",(U24/W24)) -> 1830.9125 | Y24: 515255 | Z24: =SUM(Z23+Y24) -> 7337281 | AA24: =IF(ISERROR(V24/Z24),"",(V24/Z24)) -> 0.70411492 | AB24: 500000 | AC24: =AB24+AC23 -> 6400000 | AR24: =SUM(AD24:AQ24) -> 0 | AS24: =IF(ISERROR((AR24/F24)),"",AR24/F24) | AT24: =F24-AR24+DW24 -> 0 | AV24: =A24 -> 20 | AX24: =IF(ISERROR((AW24/$F24)),"",AW24/$F24) | AZ24: =IF(ISERROR((AY24/$F24)),"",AY24/$F24) | BB24: =IF(ISERROR((BA24/$F24)),"",BA24/$F24) | BD24: =IF(ISERROR((BC24/$F24)),"",BC24/$F24) | BF24: =IF(ISERROR((BE24/$F24)),"",BE24/$F24) | BH24: =IF(ISERROR((BG24/$F24)),"",BG24/$F24) | BJ24: =IF(ISERROR((BI24/$F24)),"",BI24/$F24) | BL24: =IF(ISERROR((BK24/$F24)),"",BK24/$F24) | BN24: =IF(ISERROR((BM24/$F24)),"",BM24/$F24) | BP24: =IF(ISERROR((BO24/$F24)),"",BO24/$F24) | BR24: =IF(ISERROR((BQ24/$F24)),"",BQ24/$F24) | BT24: =IF(ISERROR((BS24/$F24)),"",BS24/$F24) | BV24: =IF(ISERROR((BU24/$F24)),"",BU24/$F24) | BX24: =IF(ISERROR((BW24/$F24)),"",BW24/$F24) | BZ24: =IF(ISERROR((BY24/$F24)),"",BY24/$F24) | CB24: =IF(ISERROR((CA24/$F24)),"",CA24/$F24) | CD24: =IF(ISERROR((CC24/$F24)),"",CC24/$F24) | CF24: =IF(ISERROR((CE24/$F24)),"",CE24/$F24) | CH24: =IF(ISERROR((CG24/$F24)),"",CG24/$F24) | CJ24: =IF(ISERROR((CI24/$F24)),"",CI24/$F24) | CL24: =IF(ISERROR((CK24/$F24)),"",CK24/$F24) | CN24: =IF(ISERROR((CM24/$F24)),"",CM24/$F24) | CP24: =IF(ISERROR((CO24/$F24)),"",CO24/$F24) | CR24: =IF(ISERROR((CQ24/$F24)),"",CQ24/$F24) | CT24: =IF(ISERROR((CS24/$F24)),"",CS24/$F24) | DB24: 20 | DC24: =B24 -> 月 | DP24: =SUM(DF24:DO24) -> 0 | DQ24: =IF(ISERROR((DP24/F24)),"",DP24/F24)
A25: 21 | B25: 火 | G25: =IF(SUM($F$5:F25)=0,"",SUM($F$5:F25)) -> 3159430 | H25: =IF(ISERROR(G25/V25),"",(G25/V25)) -> 0.5443991 | I25: {=IF($A26="",$G25/($V25-$U$5+INDIRECT(IF(_xlfn.SHEET()<6,"令和8年"&_xlfn.SHEET()+7&"月","令和9年"&_xlfn.SHEET()-5&"月")&"!$U$5")),$G25/($V26-$U$5))} -> 0.53572025 | J25: =IFERROR(G25/AC25,"") -> 0.47870152 | L25: =IF(ISERROR(K25/W25),"",(K25/W25)) -> 0 | M25: =IF(ISERROR(F25/K25),"",(F25/K25)) | N25: =IF(ISERROR(M25/X25),"",(M25/X25)) | O25: =IF(ISERROR(F25/P25),"",(F25/P25)) | Q25: =IF(ISERROR(P25/K25),"",(P25/K25)) | R25: 36 | S25: 28 | T25: 晴 | U25: 637229 | V25: =SUM(V24+U25) -> 5803518 | W25: 305 | X25: =IF(ISERROR(U25/W25),"",(U25/W25)) -> 2089.2754 | Y25: 721646 | Z25: =SUM(Z24+Y25) -> 8058927 | AA25: =IF(ISERROR(V25/Z25),"",(V25/Z25)) -> 0.72013532 | AB25: 200000 | AC25: =AB25+AC24 -> 6600000 | AR25: =SUM(AD25:AQ25) -> 0 | AS25: =IF(ISERROR((AR25/F25)),"",AR25/F25) | AT25: =F25-AR25+DW25 -> 0 | AV25: =A25 -> 21 | AX25: =IF(ISERROR((AW25/$F25)),"",AW25/$F25) | AZ25: =IF(ISERROR((AY25/$F25)),"",AY25/$F25) | BB25: =IF(ISERROR((BA25/$F25)),"",BA25/$F25) | BD25: =IF(ISERROR((BC25/$F25)),"",BC25/$F25) | BF25: =IF(ISERROR((BE25/$F25)),"",BE25/$F25) | BH25: =IF(ISERROR((BG25/$F25)),"",BG25/$F25) | BJ25: =IF(ISERROR((BI25/$F25)),"",BI25/$F25) | BL25: =IF(ISERROR((BK25/$F25)),"",BK25/$F25) | BN25: =IF(ISERROR((BM25/$F25)),"",BM25/$F25) | BP25: =IF(ISERROR((BO25/$F25)),"",BO25/$F25) | BR25: =IF(ISERROR((BQ25/$F25)),"",BQ25/$F25) | BT25: =IF(ISERROR((BS25/$F25)),"",BS25/$F25) | BV25: =IF(ISERROR((BU25/$F25)),"",BU25/$F25) | BX25: =IF(ISERROR((BW25/$F25)),"",BW25/$F25) | BZ25: =IF(ISERROR((BY25/$F25)),"",BY25/$F25) | CB25: =IF(ISERROR((CA25/$F25)),"",CA25/$F25) | CD25: =IF(ISERROR((CC25/$F25)),"",CC25/$F25) | CF25: =IF(ISERROR((CE25/$F25)),"",CE25/$F25) | CH25: =IF(ISERROR((CG25/$F25)),"",CG25/$F25) | CJ25: =IF(ISERROR((CI25/$F25)),"",CI25/$F25) | CL25: =IF(ISERROR((CK25/$F25)),"",CK25/$F25) | CN25: =IF(ISERROR((CM25/$F25)),"",CM25/$F25) | CP25: =IF(ISERROR((CO25/$F25)),"",CO25/$F25) | CR25: =IF(ISERROR((CQ25/$F25)),"",CQ25/$F25) | CT25: =IF(ISERROR((CS25/$F25)),"",CS25/$F25) | DB25: 21 | DC25: =B25 -> 火 | DP25: =SUM(DF25:DO25) -> 0 | DQ25: =IF(ISERROR((DP25/F25)),"",DP25/F25)
A26: 22 | B26: 水 | G26: =IF(SUM($F$5:F26)=0,"",SUM($F$5:F26)) -> 3159430 | H26: =IF(ISERROR(G26/V26),"",(G26/V26)) -> 0.52593056 | I26: {=IF($A27="",$G26/($V26-$U$5+INDIRECT(IF(_xlfn.SHEET()<6,"令和8年"&_xlfn.SHEET()+7&"月","令和9年"&_xlfn.SHEET()-5&"月")&"!$U$5")),$G26/($V27-$U$5))} -> 0.51532958 | J26: =IFERROR(G26/AC26,"") -> 0.46462206 | L26: =IF(ISERROR(K26/W26),"",(K26/W26)) -> 0 | M26: =IF(ISERROR(F26/K26),"",(F26/K26)) | N26: =IF(ISERROR(M26/X26),"",(M26/X26)) | O26: =IF(ISERROR(F26/P26),"",(F26/P26)) | Q26: =IF(ISERROR(P26/K26),"",(P26/K26)) | R26: 38 | S26: 27 | T26: 晴 | U26: 203796 | V26: =SUM(V25+U26) -> 6007314 | W26: 107 | X26: =IF(ISERROR(U26/W26),"",(U26/W26)) -> 1904.6355 | Y26: 267307 | Z26: =SUM(Z25+Y26) -> 8326234 | AA26: =IF(ISERROR(V26/Z26),"",(V26/Z26)) -> 0.72149233 | AB26: 200000 | AC26: =AB26+AC25 -> 6800000 | AR26: =SUM(AD26:AQ26) -> 0 | AS26: =IF(ISERROR((AR26/F26)),"",AR26/F26) | AT26: =F26-AR26+DW26 -> 0 | AV26: =A26 -> 22 | AX26: =IF(ISERROR((AW26/$F26)),"",AW26/$F26) | AZ26: =IF(ISERROR((AY26/$F26)),"",AY26/$F26) | BB26: =IF(ISERROR((BA26/$F26)),"",BA26/$F26) | BD26: =IF(ISERROR((BC26/$F26)),"",BC26/$F26) | BF26: =IF(ISERROR((BE26/$F26)),"",BE26/$F26) | BH26: =IF(ISERROR((BG26/$F26)),"",BG26/$F26) | BJ26: =IF(ISERROR((BI26/$F26)),"",BI26/$F26) | BL26: =IF(ISERROR((BK26/$F26)),"",BK26/$F26) | BN26: =IF(ISERROR((BM26/$F26)),"",BM26/$F26) | BP26: =IF(ISERROR((BO26/$F26)),"",BO26/$F26) | BR26: =IF(ISERROR((BQ26/$F26)),"",BQ26/$F26) | BT26: =IF(ISERROR((BS26/$F26)),"",BS26/$F26) | BV26: =IF(ISERROR((BU26/$F26)),"",BU26/$F26) | BX26: =IF(ISERROR((BW26/$F26)),"",BW26/$F26) | BZ26: =IF(ISERROR((BY26/$F26)),"",BY26/$F26) | CB26: =IF(ISERROR((CA26/$F26)),"",CA26/$F26) | CD26: =IF(ISERROR((CC26/$F26)),"",CC26/$F26) | CF26: =IF(ISERROR((CE26/$F26)),"",CE26/$F26) | CH26: =IF(ISERROR((CG26/$F26)),"",CG26/$F26) | CJ26: =IF(ISERROR((CI26/$F26)),"",CI26/$F26) | CL26: =IF(ISERROR((CK26/$F26)),"",CK26/$F26) | CN26: =IF(ISERROR((CM26/$F26)),"",CM26/$F26) | CP26: =IF(ISERROR((CO26/$F26)),"",CO26/$F26) | CR26: =IF(ISERROR((CQ26/$F26)),"",CQ26/$F26) | CT26: =IF(ISERROR((CS26/$F26)),"",CS26/$F26) | DB26: 22 | DC26: =B26 -> 水 | DP26: =SUM(DF26:DO26) -> 0 | DQ26: =IF(ISERROR((DP26/F26)),"",DP26/F26)
